Workbook

Sheet 缺货汇总
A1: 数据日期 | B1: 物料号 | C1: 物料名称 | D1: 品牌 | E1: 产品分类 | F1: ABC分类 | G1: 大仓库存箱数 | H1: 大仓供应情况 | I1: RDC缺货总支数 | J1: RDC缺货总金额 | K1: RDC缺货总箱数 | L1: RD在途总箱数 | M1: 涉及RDC数量 | N1: 华北RDC | P1: 西南RDC | R1: 东北RDC | T1: 华中RDC | V1: 华南RDC | X1: 华东RDC | Z1: 西北RDC
N2: 缺货箱数 | O2: 在途箱数 | P2: 缺货箱数 | Q2: 在途箱数 | R2: 缺货箱数 | S2: 在途箱数 | T2: 缺货箱数 | U2: 在途箱数 | V2: 缺货箱数 | W2: 在途箱数 | X2: 缺货箱数 | Y2: 在途箱数 | Z2: 缺货箱数 | AA2: 在途箱数
A3: 46274 | B3: 10302 | C3: 高夫净源控油清爽洁面膏100G | D3: 高夫 | E3: 常规品 | F3: A | G3: 6 | I3: 10800 | J3: 35985.6 | K3: 225 | L3: 625 | M3: 6 | N3: 2 | O3: 65 | P3: 10 | Q3: 45 | R3: 26 | S3: 95 | T3: 110 | U3: 210 | V3: 39 | W3: 45 | X3: 0 | Y3: 0 | Z3: 38 | AA3: 165
A4: 46274 | B4: 89025 | C4: 雅霜80G | D4: 传统 | E4: 常规品 | F4: A | G4: 21308 | I4: 14760 | J4: 29505.24 | K4: 246 | L4: 58 | M4: 2 | N4: 224 | O4: 0 | P4: 0 | Q4: 0 | R4: 0 | S4: 0 | T4: 0 | U4: 0 | V4: 0 | W4: 0 | X4: 0 | Y4: 0 | Z4: 22 | AA4: 58
A5: 46274 | B5: 40262 | C5: 家安薏米高效餐具净1.18KG | D5: 家安 | E5: 常规品 | F5: C | G5: 1 | H5: 整体缺货 | I5: 4136 | J5: 24183.192 | K5: 517 | L5: 235 | M5: 1 | N5: 0 | O5: 0 | P5: 0 | Q5: 0 | R5: 517 | S5: 235 | T5: 0 | U5: 0 | V5: 0 | W5: 0 | X5: 0 | Y5: 0 | Z5: 0 | AA5: 0
A6: 46274 | B6: 10304 | C6: 高夫净源控油磨砂洁面乳100G | D6: 高夫 | E6: 常规品 | F6: A | G6: 0 | H6: 整体缺货 | I6: 5136 | J6: 17960.592 | K6: 107 | L6: 0 | M6: 4 | N6: 1 | O6: 0 | P6: 9 | Q6: 0 | R6: 0 | S6: 0 | T6: 79 | U6: 0 | V6: 18 | W6: 0 | X6: 0 | Y6: 0 | Z6: 0 | AA6: 0
A7: 46274 | B7: 81011 | C7: 40.5G大号友谊护肤脂 | D7: 传统 | E7: 常规品 | F7: A | G7: 3011 | I7: 11400 | J7: 14478 | K7: 57 | L7: 45 | M7: 1 | N7: 0 | O7: 0 | P7: 0 | Q7: 0 | R7: 0 | S7: 0 | T7: 0 | U7: 0 | V7: 57 | W7: 45 | X7: 0 | Y7: 0 | Z7: 0 | AA7: 0
A8: 46274 | B8: 36467 | C8: 启初宝宝洗发沐浴露620ML | D8: 启初 | E8: 常规品 | F8: B | G8: 0 | H8: 整体缺货 | I8: 1104 | J8: 10907.52 | K8: 138 | L8: 0 | M8: 4 | N8: 0 | O8: 0 | P8: 1 | Q8: 0 | R8: 0 | S8: 0 | T8: 65 | U8: 0 | V8: 68 | W8: 0 | X8: 0 | Y8: 0 | Z8: 4 | AA8: 0
A9: 46274 | B9: 72148 | C9: 六神清爽香氛沐浴露（雨后栀子香型）100G | D9: 六神 | E9: 常规品 | F9: A | G9: 975 | I9: 3288 | J9: 8732.928 | K9: 137 | L9: 0 | M9: 1 | N9: 0 | O9: 0 | P9: 0 | Q9: 0 | R9: 0 | S9: 0 | T9: 137 | U9: 0 | V9: 0 | W9: 0 | X9: 0 | Y9: 0 | Z9: 0 | AA9: 0
A10: 46274 | B10: 36299 | C10: 启初婴儿多效倍润面霜40G送启初婴儿水嫩保湿露60ML | D10: 启初 | E10: 促销装 | F10: C | G10: 432 | I10: 768 | J10: 7282.944 | K10: 32 | L10: 26 | M10: 1 | N10: 0 | O10: 0 | P10: 0 | Q10: 0 | R10: 0 | S10: 0 | T10: 32 | U10: 26 | V10: 0 | W10: 0 | X10: 0 | Y10: 0 | Z10: 0 | AA10: 0
A11: 46274 | B11: 72141 | C11: 六神清爽香氛沐浴露（雨后栀子香型）620G | D11: 六神 | E11: 常规品 | F11: A | G11: 0 | H11: 整体缺货 | I11: 590 | J11: 5026.8 | K11: 59 | L11: 20 | M11: 2 | N11: 0 | O11: 0 | P11: 8 | Q11: 0 | R11: 0 | S11: 0 | T11: 51 | U11: 20 | V11: 0 | W11: 0 | X11: 0 | Y11: 0 | Z11: 0 | AA11: 0
A12: 46274 | B12: 10303 | C12: 高夫净源控油舒缓洁面乳100G | D12: 高夫 | E12: 常规品 | F12: A | G12: 1 | H12: 整体缺货 | I12: 1488 | J12: 4874.688 | K12: 31 | L12: 0 | M12: 1 | N12: 0 | O12: 0 | P12: 0 | Q12: 0 | R12: 0 | S12: 0 | T12: 31 | U12: 0 | V12: 0 | W12: 0 | X12: 0 | Y12: 0 | Z12: 0 | AA12: 0
A13: 46274 | B13: 36348 | C13: 启初幼儿洗发沐浴露（好奇宝宝）580ML | D13: 启初 | E13: 常规品 | F13: C | G13: 126 | I13: 300 | J13: 3988.8 | K13: 25 | L13: 49 | M13: 1 | N13: 0 | O13: 0 | P13: 0 | Q13: 0 | R13: 0 | S13: 0 | T13: 25 | U13: 49 | V13: 0 | W13: 0 | X13: 0 | Y13: 0 | Z13: 0 | AA13: 0
A14: 46274 | B14: 36266 | C14: 启初婴儿水润保湿面霜40G | D14: 启初 | E14: 常规品 | F14: A | G14: 1208 | I14: 936 | J14: 3975.192 | K14: 39 | L14: 73 | M14: 1 | N14: 0 | O14: 0 | P14: 0 | Q14: 0 | R14: 0 | S14: 0 | T14: 0 | U14: 0 | V14: 39 | W14: 73 | X14: 0 | Y14: 0 | Z14: 0 | AA14: 0
A15: 46274 | B15: 72139 | C15: 六神清爽香氛沐浴露（深海龙涎香型）620G | D15: 六神 | E15: 常规品 | F15: A | G15: 2 | I15: 360 | J15: 3672.36 | K15: 36 | L15: 42 | M15: 2 | N15: 21 | O15: 12 | P15: 0 | Q15: 0 | R15: 0 | S15: 0 | T15: 15 | U15: 30 | V15: 0 | W15: 0 | X15: 0 | Y15: 0 | Z15: 0 | AA15: 0
A16: 46274 | B16: 20918 | C16: 六神清香爽肤沐浴露700G惊爆价 | D16: 六神 | E16: 常规品 | F16: A | G16: 9939 | I16: 544 | J16: 3207.424 | K16: 68 | L16: 56 | M16: 3 | N16: 0 | O16: 0 | P16: 57 | Q16: 55 | R16: 0 | S16: 0 | T16: 0 | U16: 0 | V16: 10 | W16: 0 | X16: 0 | Y16: 0 | Z16: 1 | AA16: 1
A17: 46274 | B17: 20871 | C17: 六神清凉保湿双支装（清凉+清新）700G*2 | D17: 六神 | E17: 促销装 | F17: C | G17: 6688 | I17: 144 | J17: 2397.888 | K17: 36 | L17: 40 | M17: 2 | N17: 0 | O17: 0 | P17: 0 | Q17: 0 | R17: 0 | S17: 0 | T17: 10 | U17: 40 | V17: 26 | W17: 0 | X17: 0 | Y17: 0 | Z17: 0 | AA17: 0
A18: 46274 | B18: 89008 | C18: 雅霜50G | D18: 传统 | E18: 常规品 | F18: C | G18: 1304 | I18: 4500 | J18: 2313 | K18: 15 | L18: 0 | M18: 1 | N18: 0 | O18: 0 | P18: 0 | Q18: 0 | R18: 0 | S18: 0 | T18: 15 | U18: 0 | V18: 0 | W18: 0 | X18: 0 | Y18: 0 | Z18: 0 | AA18: 0
A19: 46274 | B19: 72092 | C19: 六神20%羟哌酯驱蚊花露水（雨后栀子）中样10ML | D19: 六神 | E19: 非卖品 | F19: A | G19: 316 | I19: 960 | J19: 2233.92 | K19: 10 | L19: 10 | M19: 1 | N19: 0 | O19: 0 | P19: 0 | Q19: 0 | R19: 0 | S19: 0 | T19: 10 | U19: 10 | V19: 0 | W19: 0 | X19: 0 | Y19: 0 | Z19: 0 | AA19: 0
A20: 46274 | B20: 09805 | C20: 美加净滋润修护型护手霜75G | D20: 美加净 | E20: 常规品 | F20: C | G20: 1 | H20: 整体缺货 | I20: 1152 | J20: 2062.08 | K20: 32 | L20: 17 | M20: 1 | N20: 0 | O20: 0 | P20: 0 | Q20: 0 | R20: 0 | S20: 0 | T20: 32 | U20: 17 | V20: 0 | W20: 0 | X20: 0 | Y20: 0 | Z20: 0 | AA20: 0
A21: 46274 | B21: 09711 | C21: 美加净银耳珍珠维生素C菁华莹亮凝露100ML | D21: 美加净 | E21: 常规品 | F21: B | G21: 0 | H21: 整体缺货 | I21: 912 | J21: 2045.616 | K21: 19 | L21: 0 | M21: 3 | N21: 2 | O21: 0 | P21: 8 | Q21: 0 | R21: 0 | S21: 0 | T21: 9 | U21: 0 | V21: 0 | W21: 0 | X21: 0 | Y21: 0 | Z21: 0 | AA21: 0
A22: 46274 | B22: 10134 | C22: 高夫锐智多效尊享护肤三部曲礼盒120G+75ML+75ML+15ML*3+25G | D22: 高夫 | E22: 促销装 | F22: B | G22: 161 | I22: 35 | J22: 1933.155 | K22: 5 | L22: 0 | M22: 1 | N22: 0 | O22: 0 | P22: 0 | Q22: 0 | R22: 0 | S22: 0 | T22: 0 | U22: 0 | V22: 0 | W22: 0 | X22: 0 | Y22: 0 | Z22: 5 | AA22: 0
A23: 46274 | B23: 72140 | C23: 六神清爽香氛沐浴露（山野青柚香型）620G | D23: 六神 | E23: 常规品 | F23: A | G23: 1145 | I23: 170 | J23: 1823.25 | K23: 17 | L23: 11 | M23: 1 | N23: 0 | O23: 0 | P23: 0 | Q23: 0 | R23: 0 | S23: 0 | T23: 17 | U23: 11 | V23: 0 | W23: 0 | X23: 0 | Y23: 0 | Z23: 0 | AA23: 0
A24: 46274 | B24: 20877 | C24: 六神清凉爽肤沐浴露750G | D24: 六神 | E24: 常规品 | F24: A | G24: 3508 | I24: 272 | J24: 1723.664 | K24: 34 | L24: 48 | M24: 1 | N24: 0 | O24: 0 | P24: 0 | Q24: 0 | R24: 0 | S24: 0 | T24: 34 | U24: 48 | V24: 0 | W24: 0 | X24: 0 | Y24: 0 | Z24: 0 | AA24: 0
A25: 46274 | B25: 30155 | C25: 高夫古龙水 | D25: 高夫 | E25: 常规品 | F25: A | G25: 20 | I25: 108 | J25: 1621.836 | K25: 3 | L25: 0 | M25: 1 | N25: 0 | O25: 0 | P25: 0 | Q25: 0 | R25: 0 | S25: 0 | T25: 0 | U25: 0 | V25: 0 | W25: 0 | X25: 0 | Y25: 0 | Z25: 3 | AA25: 0
A26: 46274 | B26: 40324 | C26: 家安酵素净护洗衣液-阳光净菌1KG | D26: 家安 | E26: 常规品 | F26: B | G26: 6993 | I26: 240 | J26: 1496.88 | K26: 30 | L26: 169 | M26: 1 | N26: 0 | O26: 0 | P26: 0 | Q26: 0 | R26: 30 | S26: 169 | T26: 0 | U26: 0 | V26: 0 | W26: 0 | X26: 0 | Y26: 0 | Z26: 0 | AA26: 0
A27: 46274 | B27: 83001 | C27: 春蕾发乳95G | D27: 传统 | E27: 常规品 | F27: C | G27: 387 | I27: 720 | J27: 1404 | K27: 6 | L27: 25 | M27: 1 | N27: 6 | O27: 25 | P27: 0 | Q27: 0 | R27: 0 | S27: 0 | T27: 0 | U27: 0 | V27: 0 | W27: 0 | X27: 0 | Y27: 0 | Z27: 0 | AA27: 0
A28: 46274 | B28: 08472 | C28: 美加净营养发乳(100G) | D28: 美加净 | E28: 常规品 | F28: C | G28: 266 | I28: 640 | J28: 1381.76 | K28: 8 | L28: 0 | M28: 1 | N28: 0 | O28: 0 | P28: 0 | Q28: 0 | R28: 0 | S28: 0 | T28: 8 | U28: 0 | V28: 0 | W28: 0 | X28: 0 | Y28: 0 | Z28: 0 | AA28: 0
A29: 46274 | B29: 19723 | C29: 195ML上海花露水 | D29: 上海 | E29: 常规品 | F29: A | G29: 9645 | I29: 600 | J29: 1356 | K29: 20 | L29: 10 | M29: 1 | N29: 0 | O29: 0 | P29: 0 | Q29: 0 | R29: 20 | S29: 10 | T29: 0 | U29: 0 | V29: 0 | W29: 0 | X29: 0 | Y29: 0 | Z29: 0 | AA29: 0
A30: 46274 | B30: 20869 | C30: 六神菁萃沐浴露双支特惠装（温润+舒缓）700G*2 | D30: 六神 | E30: 促销装 | F30: C | G30: 1222 | I30: 60 | J30: 1343.4 | K30: 15 | L30: 44 | M30: 1 | N30: 0 | O30: 0 | P30: 0 | Q30: 0 | R30: 0 | S30: 0 | T30: 15 | U30: 44 | V30: 0 | W30: 0 | X30: 0 | Y30: 0 | Z30: 0 | AA30: 0
A31: 46274 | B31: 40336 | C31: 家安酵素净护洗衣皂-超凡净透（三块装）202GX3 | D31: 家安 | E31: 常规品 | F31: A | G31: 15149 | I31: 252 | J31: 1212.624 | K31: 21 | L31: 1116 | M31: 1 | N31: 21 | O31: 1116 | P31: 0 | Q31: 0 | R31: 0 | S31: 0 | T31: 0 | U31: 0 | V31: 0 | W31: 0 | X31: 0 | Y31: 0 | Z31: 0 | AA31: 0
A32: 46274 | B32: 72123 | C32: 六神冰凉劲爽沐浴露700G 惊爆价700G | D32: 六神 | E32: 常规品 | F32: B | G32: 5878 | I32: 192 | J32: 1211.328 | K32: 24 | L32: 0 | M32: 2 | N32: 0 | O32: 0 | P32: 2 | Q32: 0 | R32: 0 | S32: 0 | T32: 22 | U32: 0 | V32: 0 | W32: 0 | X32: 0 | Y32: 0 | Z32: 0 | AA32: 0
A33: 46274 | B33: 20812 | C33: 六神舒缓健肤沐浴露（加量装）750ML | D33: 六神 | E33: 促销装 | F33: C | G33: 452 | I33: 120 | J33: 1193.28 | K33: 15 | L33: 15 | M33: 1 | N33: 0 | O33: 0 | P33: 15 | Q33: 15 | R33: 0 | S33: 0 | T33: 0 | U33: 0 | V33: 0 | W33: 0 | X33: 0 | Y33: 0 | Z33: 0 | AA33: 0
... A36: 46274 | B36: 40266 | C36: 家安米精华餐具净（两瓶装）752G*2 | D36: 家安 | E36: 促销装 | F36: C | G36: 104 | I36: 90 | J36: 872.55 | K36: 15 | L36: 15 | M36: 1 | N36: 0 | O36: 0 | P36: 15 | Q36: 15 | R36: 0 | S36: 0 | T36: 0 | U36: 0 | V36: 0 | W36: 0 | X36: 0 | Y36: 0 | Z36: 0 | AA36: 0
A37: 46274 | B37: 09657 | C37: 美加净银耳珍珠维生素E特惠套装100ML+50G | D37: 美加净 | E37: 常规品 | F37: C | G37: 4 | H37: 供应紧张 | I37: 120 | J37: 812.64 | K37: 3 | L37: 0 | M37: 1 | N37: 0 | O37: 0 | P37: 0 | Q37: 0 | R37: 0 | S37: 0 | T37: 3 | U37: 0 | V37: 0 | W37: 0 | X37: 0 | Y37: 0 | Z37: 0 | AA37: 0
A38: 46274 | B38: 72186 | C38: 六神清爽香氛洗护旅行装（山野青柚香）45G+45G+45G | D38: 六神 | E38: 促销装 | F38: B | G38: 3443 | I38: 96 | J38: 741.696 | K38: 4 | L38: 4 | M38: 1 | N38: 0 | O38: 0 | P38: 0 | Q38: 0 | R38: 4 | S38: 4 | T38: 0 | U38: 0 | V38: 0 | W38: 0 | X38: 0 | Y38: 0 | Z38: 0 | AA38: 0
A39: 46274 | B39: 08746 | C39: 美加净保湿润肤霜80G | D39: 美加净 | E39: 常规品 | F39: A | G39: 896 | I39: 192 | J39: 705.216 | K39: 4 | L39: 4 | M39: 1 | N39: 0 | O39: 0 | P39: 0 | Q39: 0 | R39: 4 | S39: 4 | T39: 0 | U39: 0 | V39: 0 | W39: 0 | X39: 0 | Y39: 0 | Z39: 0 | AA39: 0
A40: 46274 | B40: 09649 | C40: 美加净酵米焕活保湿护肤套装（150ML+100ML+50G） | D40: 美加净 | E40: 常规品 | F40: B | G40: 576 | I40: 30 | J40: 644.22 | K40: 5 | L40: 0 | M40: 1 | N40: 0 | O40: 0 | P40: 0 | Q40: 0 | R40: 0 | S40: 0 | T40: 0 | U40: 0 | V40: 5 | W40: 0 | X40: 0 | Y40: 0 | Z40: 0 | AA40: 0
A41: 46274 | B41: 36113 | C41: 启初婴儿柔护洗衣液1L | D41: 启初 | E41: 常规品 | F41: Z | G41: 547 | I41: 56 | J41: 598.416 | K41: 7 | L41: 0 | M41: 1 | N41: 0 | O41: 0 | P41: 0 | Q41: 0 | R41: 0 | S41: 0 | T41: 0 | U41: 0 | V41: 7 | W41: 0 | X41: 0 | Y41: 0 | Z41: 0 | AA41: 0
A42: 46274 | B42: 20955 | C42: 六神清透盈润沐浴露750G | D42: 六神 | E42: 常规品 | F42: C | G42: 1363 | I42: 80 | J42: 551.28 | K42: 10 | L42: 0 | M42: 1 | N42: 0 | O42: 0 | P42: 0 | Q42: 0 | R42: 0 | S42: 0 | T42: 10 | U42: 0 | V42: 0 | W42: 0 | X42: 0 | Y42: 0 | Z42: 0 | AA42: 0
...

Sheet 总体订单满足情况
A1: 月度订单满足率 | H1: RDC日订单满足率 | P1: 品牌月度订单满足率
A2: RDC | B2: 订单支数 | C2: 总履约排单数 | D2: 首日订单排单数 | E2: 月订单满足率 | F2: 日订单满足率 | H2: 日期\RDC | I2: 华南RDC | J2: 华北RDC | K2: 东北RDC | L2: 西北RDC | M2: 华中RDC | N2: 西南RDC | P2: 品牌\RDC | Q2: 华南RDC | R2: 华北RDC | S2: 东北RDC | T2: 西北RDC | U2: 华中RDC | V2: 西南RDC
A3: 华南RDC | B3: =SUMIF(订单明细!I:I,总体订单满足情况!A:A,订单明细!J:J) -> 251127 | C3: =SUMIF(订单明细!I:I,总体订单满足情况!A:A,订单明细!L:L) -> 249385 | D3: =SUMIF(订单明细!I:I,总体订单满足情况!A3:A9,订单明细!K:K) -> 234677 | E3: =C3/B3 -> 0.99306327 | F3: =D3/B3 -> 0.9344953 | H3: 46266 | I3: =IFERROR(SUMIFS(订单明细!$K:$K,订单明细!$A:$A,总体订单满足情况!$H:$H,订单明细!$I:$I,总体订单满足情况!I$2)/SUMIFS(订单明细!$J:$J,订单明细!$A:$A,总体订单满足情况!$H:$H,订单明细!$I:$I,总体订单满足情况!I$2),"") -> 0.84425278 | J3: =IFERROR(SUMIFS(订单明细!$K:$K,订单明细!$A:$A,总体订单满足情况!$H:$H,订单明细!$I:$I,总体订单满足情况!J$2)/SUMIFS(订单明细!$J:$J,订单明细!$A:$A,总体订单满足情况!$H:$H,订单明细!$I:$I,总体订单满足情况!J$2),"") -> 0.79129547 | K3: =IFERROR(SUMIFS(订单明细!$K:$K,订单明细!$A:$A,总体订单满足情况!$H:$H,订单明细!$I:$I,总体订单满足情况!K$2)/SUMIFS(订单明细!$J:$J,订单明细!$A:$A,总体订单满足情况!$H:$H,订单明细!$I:$I,总体订单满足情况!K$2),"") -> 0.74239291 | L3: =IFERROR(SUMIFS(订单明细!$K:$K,订单明细!$A:$A,总体订单满足情况!$H:$H,订单明细!$I:$I,总体订单满足情况!L$2)/SUMIFS(订单明细!$J:$J,订单明细!$A:$A,总体订单满足情况!$H:$H,订单明细!$I:$I,总体订单满足情况!L$2),"") -> 0.9033267 | M3: =IFERROR(SUMIFS(订单明细!$K:$K,订单明细!$A:$A,总体订单满足情况!$H:$H,订单明细!$I:$I,总体订单满足情况!M$2)/SUMIFS(订单明细!$J:$J,订单明细!$A:$A,总体订单满足情况!$H:$H,订单明细!$I:$I,总体订单满足情况!M$2),"") -> 0.94086516 | N3: =IFERROR(SUMIFS(订单明细!$K:$K,订单明细!$A:$A,总体订单满足情况!$H:$H,订单明细!$I:$I,总体订单满足情况!N$2)/SUMIFS(订单明细!$J:$J,订单明细!$A:$A,总体订单满足情况!$H:$H,订单明细!$I:$I,总体订单满足情况!N$2),"") -> 0.83039494 | P3: 六神 | Q3: =IFERROR(SUMIFS(订单明细!$L:$L,订单明细!$D:$D,总体订单满足情况!$P:$P,订单明细!$I:$I,总体订单满足情况!Q$2)/SUMIFS(订单明细!$J:$J,订单明细!$D:$D,总体订单满足情况!$P:$P,订单明细!$I:$I,总体订单满足情况!Q$2),"") -> 0.99847714 | R3: =IFERROR(SUMIFS(订单明细!$L:$L,订单明细!$D:$D,总体订单满足情况!$P:$P,订单明细!$I:$I,总体订单满足情况!R$2)/SUMIFS(订单明细!$J:$J,订单明细!$D:$D,总体订单满足情况!$P:$P,订单明细!$I:$I,总体订单满足情况!R$2),"") -> 0.99227414 | S3: =IFERROR(SUMIFS(订单明细!$L:$L,订单明细!$D:$D,总体订单满足情况!$P:$P,订单明细!$I:$I,总体订单满足情况!S$2)/SUMIFS(订单明细!$J:$J,订单明细!$D:$D,总体订单满足情况!$P:$P,订单明细!$I:$I,总体订单满足情况!S$2),"") -> 0.99332192 | T3: =IFERROR(SUMIFS(订单明细!$L:$L,订单明细!$D:$D,总体订单满足情况!$P:$P,订单明细!$I:$I,总体订单满足情况!T$2)/SUMIFS(订单明细!$J:$J,订单明细!$D:$D,总体订单满足情况!$P:$P,订单明细!$I:$I,总体订单满足情况!T$2),"") -> 0.99915086 | U3: =IFERROR(SUMIFS(订单明细!$L:$L,订单明细!$D:$D,总体订单满足情况!$P:$P,订单明细!$I:$I,总体订单满足情况!U$2)/SUMIFS(订单明细!$J:$J,订单明细!$D:$D,总体订单满足情况!$P:$P,订单明细!$I:$I,总体订单满足情况!U$2),"") -> 0.96684171 | V3: =IFERROR(SUMIFS(订单明细!$L:$L,订单明细!$D:$D,总体订单满足情况!$P:$P,订单明细!$I:$I,总体订单满足情况!V$2)/SUMIFS(订单明细!$J:$J,订单明细!$D:$D,总体订单满足情况!$P:$P,订单明细!$I:$I,总体订单满足情况!V$2),"") -> 0.98825911
A4: 华北RDC | B4: =SUMIF(订单明细!I:I,总体订单满足情况!A:A,订单明细!J:J) -> 132329 | C4: =SUMIF(订单明细!I:I,总体订单满足情况!A:A,订单明细!L:L) -> 130657 | D4: =SUMIF(订单明细!I:I,总体订单满足情况!A4:A10,订单明细!K:K) -> 98915 | E4: =C4/B4 -> 0.98736483 | F4: =D4/B4 -> 0.74749299 | H4: 46267 | I4: =IFERROR(SUMIFS(订单明细!$K:$K,订单明细!$A:$A,总体订单满足情况!$H:$H,订单明细!$I:$I,总体订单满足情况!I$2)/SUMIFS(订单明细!$J:$J,订单明细!$A:$A,总体订单满足情况!$H:$H,订单明细!$I:$I,总体订单满足情况!I$2),"") -> 0.95888285 | J4: =IFERROR(SUMIFS(订单明细!$K:$K,订单明细!$A:$A,总体订单满足情况!$H:$H,订单明细!$I:$I,总体订单满足情况!J$2)/SUMIFS(订单明细!$J:$J,订单明细!$A:$A,总体订单满足情况!$H:$H,订单明细!$I:$I,总体订单满足情况!J$2),"") -> 0.24358974 | K4: =IFERROR(SUMIFS(订单明细!$K:$K,订单明细!$A:$A,总体订单满足情况!$H:$H,订单明细!$I:$I,总体订单满足情况!K$2)/SUMIFS(订单明细!$J:$J,订单明细!$A:$A,总体订单满足情况!$H:$H,订单明细!$I:$I,总体订单满足情况!K$2),"") -> 0.92605634 | L4: =IFERROR(SUMIFS(订单明细!$K:$K,订单明细!$A:$A,总体订单满足情况!$H:$H,订单明细!$I:$I,总体订单满足情况!L$2)/SUMIFS(订单明细!$J:$J,订单明细!$A:$A,总体订单满足情况!$H:$H,订单明细!$I:$I,总体订单满足情况!L$2),"") -> 0.95879378 | M4: =IFERROR(SUMIFS(订单明细!$K:$K,订单明细!$A:$A,总体订单满足情况!$H:$H,订单明细!$I:$I,总体订单满足情况!M$2)/SUMIFS(订单明细!$J:$J,订单明细!$A:$A,总体订单满足情况!$H:$H,订单明细!$I:$I,总体订单满足情况!M$2),"") -> 0.73020341 | N4: =IFERROR(SUMIFS(订单明细!$K:$K,订单明细!$A:$A,总体订单满足情况!$H:$H,订单明细!$I:$I,总体订单满足情况!N$2)/SUMIFS(订单明细!$J:$J,订单明细!$A:$A,总体订单满足情况!$H:$H,订单明细!$I:$I,总体订单满足情况!N$2),"") -> 0.7969176 | P4: 美加净 | Q4: =IFERROR(SUMIFS(订单明细!$L:$L,订单明细!$D:$D,总体订单满足情况!$P:$P,订单明细!$I:$I,总体订单满足情况!Q$2)/SUMIFS(订单明细!$J:$J,订单明细!$D:$D,总体订单满足情况!$P:$P,订单明细!$I:$I,总体订单满足情况!Q$2),"") -> 0.99946579 | R4: =IFERROR(SUMIFS(订单明细!$L:$L,订单明细!$D:$D,总体订单满足情况!$P:$P,订单明细!$I:$I,总体订单满足情况!R$2)/SUMIFS(订单明细!$J:$J,订单明细!$D:$D,总体订单满足情况!$P:$P,订单明细!$I:$I,总体订单满足情况!R$2),"") -> 0.9986263 | S4: =IFERROR(SUMIFS(订单明细!$L:$L,订单明细!$D:$D,总体订单满足情况!$P:$P,订单明细!$I:$I,总体订单满足情况!S$2)/SUMIFS(订单明细!$J:$J,订单明细!$D:$D,总体订单满足情况!$P:$P,订单明细!$I:$I,总体订单满足情况!S$2),"") -> 0.99483557 | T4: =IFERROR(SUMIFS(订单明细!$L:$L,订单明细!$D:$D,总体订单满足情况!$P:$P,订单明细!$I:$I,总体订单满足情况!T$2)/SUMIFS(订单明细!$J:$J,订单明细!$D:$D,总体订单满足情况!$P:$P,订单明细!$I:$I,总体订单满足情况!T$2),"") -> 0.99788989 | U4: =IFERROR(SUMIFS(订单明细!$L:$L,订单明细!$D:$D,总体订单满足情况!$P:$P,订单明细!$I:$I,总体订单满足情况!U$2)/SUMIFS(订单明细!$J:$J,订单明细!$D:$D,总体订单满足情况!$P:$P,订单明细!$I:$I,总体订单满足情况!U$2),"") -> 0.98893073 | V4: =IFERROR(SUMIFS(订单明细!$L:$L,订单明细!$D:$D,总体订单满足情况!$P:$P,订单明细!$I:$I,总体订单满足情况!V$2)/SUMIFS(订单明细!$J:$J,订单明细!$D:$D,总体订单满足情况!$P:$P,订单明细!$I:$I,总体订单满足情况!V$2),"") -> 0.99454561
A5: 东北RDC | B5: =SUMIF(订单明细!I:I,总体订单满足情况!A:A,订单明细!J:J) -> 105143 | C5: =SUMIF(订单明细!I:I,总体订单满足情况!A:A,订单明细!L:L) -> 102605 | D5: =SUMIF(订单明细!I:I,总体订单满足情况!A5:A11,订单明细!K:K) -> 84111 | E5: =C5/B5 -> 0.97586145 | F5: =D5/B5 -> 0.79996766 | H5: 46268 | I5: =IFERROR(SUMIFS(订单明细!$K:$K,订单明细!$A:$A,总体订单满足情况!$H:$H,订单明细!$I:$I,总体订单满足情况!I$2)/SUMIFS(订单明细!$J:$J,订单明细!$A:$A,总体订单满足情况!$H:$H,订单明细!$I:$I,总体订单满足情况!I$2),"") -> 0.86676681 | J5: =IFERROR(SUMIFS(订单明细!$K:$K,订单明细!$A:$A,总体订单满足情况!$H:$H,订单明细!$I:$I,总体订单满足情况!J$2)/SUMIFS(订单明细!$J:$J,订单明细!$A:$A,总体订单满足情况!$H:$H,订单明细!$I:$I,总体订单满足情况!J$2),"") -> 0.82517137 | K5: =IFERROR(SUMIFS(订单明细!$K:$K,订单明细!$A:$A,总体订单满足情况!$H:$H,订单明细!$I:$I,总体订单满足情况!K$2)/SUMIFS(订单明细!$J:$J,订单明细!$A:$A,总体订单满足情况!$H:$H,订单明细!$I:$I,总体订单满足情况!K$2),"") -> 0.88424922 | L5: =IFERROR(SUMIFS(订单明细!$K:$K,订单明细!$A:$A,总体订单满足情况!$H:$H,订单明细!$I:$I,总体订单满足情况!L$2)/SUMIFS(订单明细!$J:$J,订单明细!$A:$A,总体订单满足情况!$H:$H,订单明细!$I:$I,总体订单满足情况!L$2),"") -> 0.95266272 | M5: =IFERROR(SUMIFS(订单明细!$K:$K,订单明细!$A:$A,总体订单满足情况!$H:$H,订单明细!$I:$I,总体订单满足情况!M$2)/SUMIFS(订单明细!$J:$J,订单明细!$A:$A,总体订单满足情况!$H:$H,订单明细!$I:$I,总体订单满足情况!M$2),"") -> 0.83425224 | N5: =IFERROR(SUMIFS(订单明细!$K:$K,订单明细!$A:$A,总体订单满足情况!$H:$H,订单明细!$I:$I,总体订单满足情况!N$2)/SUMIFS(订单明细!$J:$J,订单明细!$A:$A,总体订单满足情况!$H:$H,订单明细!$I:$I,总体订单满足情况!N$2),"") -> 0.97987349 | P5: 启初 | Q5: =IFERROR(SUMIFS(订单明细!$L:$L,订单明细!$D:$D,总体订单满足情况!$P:$P,订单明细!$I:$I,总体订单满足情况!Q$2)/SUMIFS(订单明细!$J:$J,订单明细!$D:$D,总体订单满足情况!$P:$P,订单明细!$I:$I,总体订单满足情况!Q$2),"") -> 0.76054591 | R5: =IFERROR(SUMIFS(订单明细!$L:$L,订单明细!$D:$D,总体订单满足情况!$P:$P,订单明细!$I:$I,总体订单满足情况!R$2)/SUMIFS(订单明细!$J:$J,订单明细!$D:$D,总体订单满足情况!$P:$P,订单明细!$I:$I,总体订单满足情况!R$2),"") -> 0.99204244 | S5: =IFERROR(SUMIFS(订单明细!$L:$L,订单明细!$D:$D,总体订单满足情况!$P:$P,订单明细!$I:$I,总体订单满足情况!S$2)/SUMIFS(订单明细!$J:$J,订单明细!$D:$D,总体订单满足情况!$P:$P,订单明细!$I:$I,总体订单满足情况!S$2),"") -> 1 | T5: =IFERROR(SUMIFS(订单明细!$L:$L,订单明细!$D:$D,总体订单满足情况!$P:$P,订单明细!$I:$I,总体订单满足情况!T$2)/SUMIFS(订单明细!$J:$J,订单明细!$D:$D,总体订单满足情况!$P:$P,订单明细!$I:$I,总体订单满足情况!T$2),"") -> 0.98218263 | U5: =IFERROR(SUMIFS(订单明细!$L:$L,订单明细!$D:$D,总体订单满足情况!$P:$P,订单明细!$I:$I,总体订单满足情况!U$2)/SUMIFS(订单明细!$J:$J,订单明细!$D:$D,总体订单满足情况!$P:$P,订单明细!$I:$I,总体订单满足情况!U$2),"") -> 0.85389116 | V5: =IFERROR(SUMIFS(订单明细!$L:$L,订单明细!$D:$D,总体订单满足情况!$P:$P,订单明细!$I:$I,总体订单满足情况!V$2)/SUMIFS(订单明细!$J:$J,订单明细!$D:$D,总体订单满足情况!$P:$P,订单明细!$I:$I,总体订单满足情况!V$2),"") -> 0.9965812
A6: 西北RDC | B6: =SUMIF(订单明细!I:I,总体订单满足情况!A:A,订单明细!J:J) -> 72607 | C6: =SUMIF(订单明细!I:I,总体订单满足情况!A:A,订单明细!L:L) -> 69498 | D6: =SUMIF(订单明细!I:I,总体订单满足情况!A6:A12,订单明细!K:K) -> 66936 | E6: =C6/B6 -> 0.95718044 | F6: =D6/B6 -> 0.92189458 | H6: 46269 | I6: =IFERROR(SUMIFS(订单明细!$K:$K,订单明细!$A:$A,总体订单满足情况!$H:$H,订单明细!$I:$I,总体订单满足情况!I$2)/SUMIFS(订单明细!$J:$J,订单明细!$A:$A,总体订单满足情况!$H:$H,订单明细!$I:$I,总体订单满足情况!I$2),"") -> 0.96132913 | J6: =IFERROR(SUMIFS(订单明细!$K:$K,订单明细!$A:$A,总体订单满足情况!$H:$H,订单明细!$I:$I,总体订单满足情况!J$2)/SUMIFS(订单明细!$J:$J,订单明细!$A:$A,总体订单满足情况!$H:$H,订单明细!$I:$I,总体订单满足情况!J$2),"") -> 0.72105025 | K6: =IFERROR(SUMIFS(订单明细!$K:$K,订单明细!$A:$A,总体订单满足情况!$H:$H,订单明细!$I:$I,总体订单满足情况!K$2)/SUMIFS(订单明细!$J:$J,订单明细!$A:$A,总体订单满足情况!$H:$H,订单明细!$I:$I,总体订单满足情况!K$2),"") -> 0.64787927 | L6: =IFERROR(SUMIFS(订单明细!$K:$K,订单明细!$A:$A,总体订单满足情况!$H:$H,订单明细!$I:$I,总体订单满足情况!L$2)/SUMIFS(订单明细!$J:$J,订单明细!$A:$A,总体订单满足情况!$H:$H,订单明细!$I:$I,总体订单满足情况!L$2),"") -> 0.67770419 | M6: =IFERROR(SUMIFS(订单明细!$K:$K,订单明细!$A:$A,总体订单满足情况!$H:$H,订单明细!$I:$I,总体订单满足情况!M$2)/SUMIFS(订单明细!$J:$J,订单明细!$A:$A,总体订单满足情况!$H:$H,订单明细!$I:$I,总体订单满足情况!M$2),"") -> 0.92620245 | N6: =IFERROR(SUMIFS(订单明细!$K:$K,订单明细!$A:$A,总体订单满足情况!$H:$H,订单明细!$I:$I,总体订单满足情况!N$2)/SUMIFS(订单明细!$J:$J,订单明细!$A:$A,总体订单满足情况!$H:$H,订单明细!$I:$I,总体订单满足情况!N$2),"") -> 0.97691911 | P6: 家安 | Q6: =IFERROR(SUMIFS(订单明细!$L:$L,订单明细!$D:$D,总体订单满足情况!$P:$P,订单明细!$I:$I,总体订单满足情况!Q$2)/SUMIFS(订单明细!$J:$J,订单明细!$D:$D,总体订单满足情况!$P:$P,订单明细!$I:$I,总体订单满足情况!Q$2),"") -> 1 | R6: =IFERROR(SUMIFS(订单明细!$L:$L,订单明细!$D:$D,总体订单满足情况!$P:$P,订单明细!$I:$I,总体订单满足情况!R$2)/SUMIFS(订单明细!$J:$J,订单明细!$D:$D,总体订单满足情况!$P:$P,订单明细!$I:$I,总体订单满足情况!R$2),"") -> 0.97703549 | S6: =IFERROR(SUMIFS(订单明细!$L:$L,订单明细!$D:$D,总体订单满足情况!$P:$P,订单明细!$I:$I,总体订单满足情况!S$2)/SUMIFS(订单明细!$J:$J,订单明细!$D:$D,总体订单满足情况!$P:$P,订单明细!$I:$I,总体订单满足情况!S$2),"") -> 0.99015029 | T6: =IFERROR(SUMIFS(订单明细!$L:$L,订单明细!$D:$D,总体订单满足情况!$P:$P,订单明细!$I:$I,总体订单满足情况!T$2)/SUMIFS(订单明细!$J:$J,订单明细!$D:$D,总体订单满足情况!$P:$P,订单明细!$I:$I,总体订单满足情况!T$2),"") -> 1 | U6: =IFERROR(SUMIFS(订单明细!$L:$L,订单明细!$D:$D,总体订单满足情况!$P:$P,订单明细!$I:$I,总体订单满足情况!U$2)/SUMIFS(订单明细!$J:$J,订单明细!$D:$D,总体订单满足情况!$P:$P,订单明细!$I:$I,总体订单满足情况!U$2),"") -> 0.99558499 | V6: =IFERROR(SUMIFS(订单明细!$L:$L,订单明细!$D:$D,总体订单满足情况!$P:$P,订单明细!$I:$I,总体订单满足情况!V$2)/SUMIFS(订单明细!$J:$J,订单明细!$D:$D,总体订单满足情况!$P:$P,订单明细!$I:$I,总体订单满足情况!V$2),"") -> 0.99288425
A7: 华中RDC | B7: =SUMIF(订单明细!I:I,总体订单满足情况!A:A,订单明细!J:J) -> 469117 | C7: =SUMIF(订单明细!I:I,总体订单满足情况!A:A,订单明细!L:L) -> 444550 | D7: =SUMIF(订单明细!I:I,总体订单满足情况!A7:A12,订单明细!K:K) -> 416892 | E7: =C7/B7 -> 0.9476314 | F7: =D7/B7 -> 0.88867383 | H7: 46272 | I7: =IFERROR(SUMIFS(订单明细!$K:$K,订单明细!$A:$A,总体订单满足情况!$H:$H,订单明细!$I:$I,总体订单满足情况!I$2)/SUMIFS(订单明细!$J:$J,订单明细!$A:$A,总体订单满足情况!$H:$H,订单明细!$I:$I,总体订单满足情况!I$2),"") -> 0.95800405 | J7: =IFERROR(SUMIFS(订单明细!$K:$K,订单明细!$A:$A,总体订单满足情况!$H:$H,订单明细!$I:$I,总体订单满足情况!J$2)/SUMIFS(订单明细!$J:$J,订单明细!$A:$A,总体订单满足情况!$H:$H,订单明细!$I:$I,总体订单满足情况!J$2),"") -> 0.6950623 | K7: =IFERROR(SUMIFS(订单明细!$K:$K,订单明细!$A:$A,总体订单满足情况!$H:$H,订单明细!$I:$I,总体订单满足情况!K$2)/SUMIFS(订单明细!$J:$J,订单明细!$A:$A,总体订单满足情况!$H:$H,订单明细!$I:$I,总体订单满足情况!K$2),"") -> 0.80790823 | L7: =IFERROR(SUMIFS(订单明细!$K:$K,订单明细!$A:$A,总体订单满足情况!$H:$H,订单明细!$I:$I,总体订单满足情况!L$2)/SUMIFS(订单明细!$J:$J,订单明细!$A:$A,总体订单满足情况!$H:$H,订单明细!$I:$I,总体订单满足情况!L$2),"") -> 0.99469496 | M7: =IFERROR(SUMIFS(订单明细!$K:$K,订单明细!$A:$A,总体订单满足情况!$H:$H,订单明细!$I:$I,总体订单满足情况!M$2)/SUMIFS(订单明细!$J:$J,订单明细!$A:$A,总体订单满足情况!$H:$H,订单明细!$I:$I,总体订单满足情况!M$2),"") -> 0.87147441 | N7: =IFERROR(SUMIFS(订单明细!$K:$K,订单明细!$A:$A,总体订单满足情况!$H:$H,订单明细!$I:$I,总体订单满足情况!N$2)/SUMIFS(订单明细!$J:$J,订单明细!$A:$A,总体订单满足情况!$H:$H,订单明细!$I:$I,总体订单满足情况!N$2),"") -> 0.96466556 | P7: 传统 | Q7: =IFERROR(SUMIFS(订单明细!$L:$L,订单明细!$D:$D,总体订单满足情况!$P:$P,订单明细!$I:$I,总体订单满足情况!Q$2)/SUMIFS(订单明细!$J:$J,订单明细!$D:$D,总体订单满足情况!$P:$P,订单明细!$I:$I,总体订单满足情况!Q$2),"") | R7: =IFERROR(SUMIFS(订单明细!$L:$L,订单明细!$D:$D,总体订单满足情况!$P:$P,订单明细!$I:$I,总体订单满足情况!R$2)/SUMIFS(订单明细!$J:$J,订单明细!$D:$D,总体订单满足情况!$P:$P,订单明细!$I:$I,总体订单满足情况!R$2),"") | S7: =IFERROR(SUMIFS(订单明细!$L:$L,订单明细!$D:$D,总体订单满足情况!$P:$P,订单明细!$I:$I,总体订单满足情况!S$2)/SUMIFS(订单明细!$J:$J,订单明细!$D:$D,总体订单满足情况!$P:$P,订单明细!$I:$I,总体订单满足情况!S$2),"") | T7: =IFERROR(SUMIFS(订单明细!$L:$L,订单明细!$D:$D,总体订单满足情况!$P:$P,订单明细!$I:$I,总体订单满足情况!T$2)/SUMIFS(订单明细!$J:$J,订单明细!$D:$D,总体订单满足情况!$P:$P,订单明细!$I:$I,总体订单满足情况!T$2),"") | U7: =IFERROR(SUMIFS(订单明细!$L:$L,订单明细!$D:$D,总体订单满足情况!$P:$P,订单明细!$I:$I,总体订单满足情况!U$2)/SUMIFS(订单明细!$J:$J,订单明细!$D:$D,总体订单满足情况!$P:$P,订单明细!$I:$I,总体订单满足情况!U$2),"") | V7: =IFERROR(SUMIFS(订单明细!$L:$L,订单明细!$D:$D,总体订单满足情况!$P:$P,订单明细!$I:$I,总体订单满足情况!V$2)/SUMIFS(订单明细!$J:$J,订单明细!$D:$D,总体订单满足情况!$P:$P,订单明细!$I:$I,总体订单满足情况!V$2),"")
A8: 西南RDC | B8: =SUMIF(订单明细!I:I,总体订单满足情况!A:A,订单明细!J:J) -> 189009 | C8: =SUMIF(订单明细!I:I,总体订单满足情况!A:A,订单明细!L:L) -> 186641 | D8: =SUMIF(订单明细!I:I,总体订单满足情况!A8:A12,订单明细!K:K) -> 156893 | E8: =C8/B8 -> 0.9874715 | F8: =D8/B8 -> 0.83008217 | H8: 46273 | I8: =IFERROR(SUMIFS(订单明细!$K:$K,订单明细!$A:$A,总体订单满足情况!$H:$H,订单明细!$I:$I,总体订单满足情况!I$2)/SUMIFS(订单明细!$J:$J,订单明细!$A:$A,总体订单满足情况!$H:$H,订单明细!$I:$I,总体订单满足情况!I$2),"") -> 1 | J8: =IFERROR(SUMIFS(订单明细!$K:$K,订单明细!$A:$A,总体订单满足情况!$H:$H,订单明细!$I:$I,总体订单满足情况!J$2)/SUMIFS(订单明细!$J:$J,订单明细!$A:$A,总体订单满足情况!$H:$H,订单明细!$I:$I,总体订单满足情况!J$2),"") -> 0.98252537 | K8: =IFERROR(SUMIFS(订单明细!$K:$K,订单明细!$A:$A,总体订单满足情况!$H:$H,订单明细!$I:$I,总体订单满足情况!K$2)/SUMIFS(订单明细!$J:$J,订单明细!$A:$A,总体订单满足情况!$H:$H,订单明细!$I:$I,总体订单满足情况!K$2),"") -> 0.56463618 | L8: =IFERROR(SUMIFS(订单明细!$K:$K,订单明细!$A:$A,总体订单满足情况!$H:$H,订单明细!$I:$I,总体订单满足情况!L$2)/SUMIFS(订单明细!$J:$J,订单明细!$A:$A,总体订单满足情况!$H:$H,订单明细!$I:$I,总体订单满足情况!L$2),"") -> 0.92804378 | M8: =IFERROR(SUMIFS(订单明细!$K:$K,订单明细!$A:$A,总体订单满足情况!$H:$H,订单明细!$I:$I,总体订单满足情况!M$2)/SUMIFS(订单明细!$J:$J,订单明细!$A:$A,总体订单满足情况!$H:$H,订单明细!$I:$I,总体订单满足情况!M$2),"") -> 0.91792421 | N8: =IFERROR(SUMIFS(订单明细!$K:$K,订单明细!$A:$A,总体订单满足情况!$H:$H,订单明细!$I:$I,总体订单满足情况!N$2)/SUMIFS(订单明细!$J:$J,订单明细!$A:$A,总体订单满足情况!$H:$H,订单明细!$I:$I,总体订单满足情况!N$2),"") -> 0.91594788 | P8: 片仔癀 | Q8: =IFERROR(SUMIFS(订单明细!$L:$L,订单明细!$D:$D,总体订单满足情况!$P:$P,订单明细!$I:$I,总体订单满足情况!Q$2)/SUMIFS(订单明细!$J:$J,订单明细!$D:$D,总体订单满足情况!$P:$P,订单明细!$I:$I,总体订单满足情况!Q$2),"") | R8: =IFERROR(SUMIFS(订单明细!$L:$L,订单明细!$D:$D,总体订单满足情况!$P:$P,订单明细!$I:$I,总体订单满足情况!R$2)/SUMIFS(订单明细!$J:$J,订单明细!$D:$D,总体订单满足情况!$P:$P,订单明细!$I:$I,总体订单满足情况!R$2),"") | S8: =IFERROR(SUMIFS(订单明细!$L:$L,订单明细!$D:$D,总体订单满足情况!$P:$P,订单明细!$I:$I,总体订单满足情况!S$2)/SUMIFS(订单明细!$J:$J,订单明细!$D:$D,总体订单满足情况!$P:$P,订单明细!$I:$I,总体订单满足情况!S$2),"") | T8: =IFERROR(SUMIFS(订单明细!$L:$L,订单明细!$D:$D,总体订单满足情况!$P:$P,订单明细!$I:$I,总体订单满足情况!T$2)/SUMIFS(订单明细!$J:$J,订单明细!$D:$D,总体订单满足情况!$P:$P,订单明细!$I:$I,总体订单满足情况!T$2),"") | U8: =IFERROR(SUMIFS(订单明细!$L:$L,订单明细!$D:$D,总体订单满足情况!$P:$P,订单明细!$I:$I,总体订单满足情况!U$2)/SUMIFS(订单明细!$J:$J,订单明细!$D:$D,总体订单满足情况!$P:$P,订单明细!$I:$I,总体订单满足情况!U$2),"") | V8: =IFERROR(SUMIFS(订单明细!$L:$L,订单明细!$D:$D,总体订单满足情况!$P:$P,订单明细!$I:$I,总体订单满足情况!V$2)/SUMIFS(订单明细!$J:$J,订单明细!$D:$D,总体订单满足情况!$P:$P,订单明细!$I:$I,总体订单满足情况!V$2),"")
A9: 合计 | B9: =SUM(B3:B8) -> 1219332 | C9: =SUM(C3:C8) -> 1183336 | D9: =SUM(D3:D8) -> 1058424 | E9: =C9/B9 -> 0.97047892 | F9: =D9/B9 -> 0.86803594 | H9: 46274 | I9: =IFERROR(SUMIFS(订单明细!$K:$K,订单明细!$A:$A,总体订单满足情况!$H:$H,订单明细!$I:$I,总体订单满足情况!I$2)/SUMIFS(订单明细!$J:$J,订单明细!$A:$A,总体订单满足情况!$H:$H,订单明细!$I:$I,总体订单满足情况!I$2),"") -> 0.96090928 | J9: =IFERROR(SUMIFS(订单明细!$K:$K,订单明细!$A:$A,总体订单满足情况!$H:$H,订单明细!$I:$I,总体订单满足情况!J$2)/SUMIFS(订单明细!$J:$J,订单明细!$A:$A,总体订单满足情况!$H:$H,订单明细!$I:$I,总体订单满足情况!J$2),"") -> 0.98058252 | K9: =IFERROR(SUMIFS(订单明细!$K:$K,订单明细!$A:$A,总体订单满足情况!$H:$H,订单明细!$I:$I,总体订单满足情况!K$2)/SUMIFS(订单明细!$J:$J,订单明细!$A:$A,总体订单满足情况!$H:$H,订单明细!$I:$I,总体订单满足情况!K$2),"") -> 0.94368463 | L9: =IFERROR(SUMIFS(订单明细!$K:$K,订单明细!$A:$A,总体订单满足情况!$H:$H,订单明细!$I:$I,总体订单满足情况!L$2)/SUMIFS(订单明细!$J:$J,订单明细!$A:$A,总体订单满足情况!$H:$H,订单明细!$I:$I,总体订单满足情况!L$2),"") -> 0.99153322 | M9: =IFERROR(SUMIFS(订单明细!$K:$K,订单明细!$A:$A,总体订单满足情况!$H:$H,订单明细!$I:$I,总体订单满足情况!M$2)/SUMIFS(订单明细!$J:$J,订单明细!$A:$A,总体订单满足情况!$H:$H,订单明细!$I:$I,总体订单满足情况!M$2),"") -> 0.94835529 | N9: =IFERROR(SUMIFS(订单明细!$K:$K,订单明细!$A:$A,总体订单满足情况!$H:$H,订单明细!$I:$I,总体订单满足情况!N$2)/SUMIFS(订单明细!$J:$J,订单明细!$A:$A,总体订单满足情况!$H:$H,订单明细!$I:$I,总体订单满足情况!N$2),"") -> 0.9947518 | P9: 高夫 | Q9: =IFERROR(SUMIFS(订单明细!$L:$L,订单明细!$D:$D,总体订单满足情况!$P:$P,订单明细!$I:$I,总体订单满足情况!Q$2)/SUMIFS(订单明细!$J:$J,订单明细!$D:$D,总体订单满足情况!$P:$P,订单明细!$I:$I,总体订单满足情况!Q$2),"") -> 1 | R9: =IFERROR(SUMIFS(订单明细!$L:$L,订单明细!$D:$D,总体订单满足情况!$P:$P,订单明细!$I:$I,总体订单满足情况!R$2)/SUMIFS(订单明细!$J:$J,订单明细!$D:$D,总体订单满足情况!$P:$P,订单明细!$I:$I,总体订单满足情况!R$2),"") -> 0.78894472 | S9: =IFERROR(SUMIFS(订单明细!$L:$L,订单明细!$D:$D,总体订单满足情况!$P:$P,订单明细!$I:$I,总体订单满足情况!S$2)/SUMIFS(订单明细!$J:$J,订单明细!$D:$D,总体订单满足情况!$P:$P,订单明细!$I:$I,总体订单满足情况!S$2),"") -> 0.56287215 | T9: =IFERROR(SUMIFS(订单明细!$L:$L,订单明细!$D:$D,总体订单满足情况!$P:$P,订单明细!$I:$I,总体订单满足情况!T$2)/SUMIFS(订单明细!$J:$J,订单明细!$D:$D,总体订单满足情况!$P:$P,订单明细!$I:$I,总体订单满足情况!T$2),"") -> 0.70162878 | U9: =IFERROR(SUMIFS(订单明细!$L:$L,订单明细!$D:$D,总体订单满足情况!$P:$P,订单明细!$I:$I,总体订单满足情况!U$2)/SUMIFS(订单明细!$J:$J,订单明细!$D:$D,总体订单满足情况!$P:$P,订单明细!$I:$I,总体订单满足情况!U$2),"") -> 0.44235925 | V9: =IFERROR(SUMIFS(订单明细!$L:$L,订单明细!$D:$D,总体订单满足情况!$P:$P,订单明细!$I:$I,总体订单满足情况!V$2)/SUMIFS(订单明细!$J:$J,订单明细!$D:$D,总体订单满足情况!$P:$P,订单明细!$I:$I,总体订单满足情况!V$2),"") -> 0.51612903
I10: =IFERROR(SUMIFS(订单明细!$K:$K,订单明细!$A:$A,总体订单满足情况!$H:$H,订单明细!$I:$I,总体订单满足情况!I$2)/SUMIFS(订单明细!$J:$J,订单明细!$A:$A,总体订单满足情况!$H:$H,订单明细!$I:$I,总体订单满足情况!I$2),"") | J10: =IFERROR(SUMIFS(订单明细!$K:$K,订单明细!$A:$A,总体订单满足情况!$H:$H,订单明细!$I:$I,总体订单满足情况!J$2)/SUMIFS(订单明细!$J:$J,订单明细!$A:$A,总体订单满足情况!$H:$H,订单明细!$I:$I,总体订单满足情况!J$2),"") | K10: =IFERROR(SUMIFS(订单明细!$K:$K,订单明细!$A:$A,总体订单满足情况!$H:$H,订单明细!$I:$I,总体订单满足情况!K$2)/SUMIFS(订单明细!$J:$J,订单明细!$A:$A,总体订单满足情况!$H:$H,订单明细!$I:$I,总体订单满足情况!K$2),"") | L10: =IFERROR(SUMIFS(订单明细!$K:$K,订单明细!$A:$A,总体订单满足情况!$H:$H,订单明细!$I:$I,总体订单满足情况!L$2)/SUMIFS(订单明细!$J:$J,订单明细!$A:$A,总体订单满足情况!$H:$H,订单明细!$I:$I,总体订单满足情况!L$2),"") | M10: =IFERROR(SUMIFS(订单明细!$K:$K,订单明细!$A:$A,总体订单满足情况!$H:$H,订单明细!$I:$I,总体订单满足情况!M$2)/SUMIFS(订单明细!$J:$J,订单明细!$A:$A,总体订单满足情况!$H:$H,订单明细!$I:$I,总体订单满足情况!M$2),"") | N10: =IFERROR(SUMIFS(订单明细!$K:$K,订单明细!$A:$A,总体订单满足情况!$H:$H,订单明细!$I:$I,总体订单满足情况!N$2)/SUMIFS(订单明细!$J:$J,订单明细!$A:$A,总体订单满足情况!$H:$H,订单明细!$I:$I,总体订单满足情况!N$2),"") | P10: 上海 | Q10: =IFERROR(SUMIFS(订单明细!$L:$L,订单明细!$D:$D,总体订单满足情况!$P:$P,订单明细!$I:$I,总体订单满足情况!Q$2)/SUMIFS(订单明细!$J:$J,订单明细!$D:$D,总体订单满足情况!$P:$P,订单明细!$I:$I,总体订单满足情况!Q$2),"") -> 1 | R10: =IFERROR(SUMIFS(订单明细!$L:$L,订单明细!$D:$D,总体订单满足情况!$P:$P,订单明细!$I:$I,总体订单满足情况!R$2)/SUMIFS(订单明细!$J:$J,订单明细!$D:$D,总体订单满足情况!$P:$P,订单明细!$I:$I,总体订单满足情况!R$2),"") -> 1 | S10: =IFERROR(SUMIFS(订单明细!$L:$L,订单明细!$D:$D,总体订单满足情况!$P:$P,订单明细!$I:$I,总体订单满足情况!S$2)/SUMIFS(订单明细!$J:$J,订单明细!$D:$D,总体订单满足情况!$P:$P,订单明细!$I:$I,总体订单满足情况!S$2),"") -> 0 | T10: =IFERROR(SUMIFS(订单明细!$L:$L,订单明细!$D:$D,总体订单满足情况!$P:$P,订单明细!$I:$I,总体订单满足情况!T$2)/SUMIFS(订单明细!$J:$J,订单明细!$D:$D,总体订单满足情况!$P:$P,订单明细!$I:$I,总体订单满足情况!T$2),"") -> 1 | U10: =IFERROR(SUMIFS(订单明细!$L:$L,订单明细!$D:$D,总体订单满足情况!$P:$P,订单明细!$I:$I,总体订单满足情况!U$2)/SUMIFS(订单明细!$J:$J,订单明细!$D:$D,总体订单满足情况!$P:$P,订单明细!$I:$I,总体订单满足情况!U$2),"") -> 1 | V10: =IFERROR(SUMIFS(订单明细!$L:$L,订单明细!$D:$D,总体订单满足情况!$P:$P,订单明细!$I:$I,总体订单满足情况!V$2)/SUMIFS(订单明细!$J:$J,订单明细!$D:$D,总体订单满足情况!$P:$P,订单明细!$I:$I,总体订单满足情况!V$2),"") -> 1
I11: =IFERROR(SUMIFS(订单明细!$K:$K,订单明细!$A:$A,总体订单满足情况!$H:$H,订单明细!$I:$I,总体订单满足情况!I$2)/SUMIFS(订单明细!$J:$J,订单明细!$A:$A,总体订单满足情况!$H:$H,订单明细!$I:$I,总体订单满足情况!I$2),"") | J11: =IFERROR(SUMIFS(订单明细!$K:$K,订单明细!$A:$A,总体订单满足情况!$H:$H,订单明细!$I:$I,总体订单满足情况!J$2)/SUMIFS(订单明细!$J:$J,订单明细!$A:$A,总体订单满足情况!$H:$H,订单明细!$I:$I,总体订单满足情况!J$2),"") | K11: =IFERROR(SUMIFS(订单明细!$K:$K,订单明细!$A:$A,总体订单满足情况!$H:$H,订单明细!$I:$I,总体订单满足情况!K$2)/SUMIFS(订单明细!$J:$J,订单明细!$A:$A,总体订单满足情况!$H:$H,订单明细!$I:$I,总体订单满足情况!K$2),"") | L11: =IFERROR(SUMIFS(订单明细!$K:$K,订单明细!$A:$A,总体订单满足情况!$H:$H,订单明细!$I:$I,总体订单满足情况!L$2)/SUMIFS(订单明细!$J:$J,订单明细!$A:$A,总体订单满足情况!$H:$H,订单明细!$I:$I,总体订单满足情况!L$2),"") | M11: =IFERROR(SUMIFS(订单明细!$K:$K,订单明细!$A:$A,总体订单满足情况!$H:$H,订单明细!$I:$I,总体订单满足情况!M$2)/SUMIFS(订单明细!$J:$J,订单明细!$A:$A,总体订单满足情况!$H:$H,订单明细!$I:$I,总体订单满足情况!M$2),"") | N11: =IFERROR(SUMIFS(订单明细!$K:$K,订单明细!$A:$A,总体订单满足情况!$H:$H,订单明细!$I:$I,总体订单满足情况!N$2)/SUMIFS(订单明细!$J:$J,订单明细!$A:$A,总体订单满足情况!$H:$H,订单明细!$I:$I,总体订单满足情况!N$2),"")
I12: =IFERROR(SUMIFS(订单明细!$K:$K,订单明细!$A:$A,总体订单满足情况!$H:$H,订单明细!$I:$I,总体订单满足情况!I$2)/SUMIFS(订单明细!$J:$J,订单明细!$A:$A,总体订单满足情况!$H:$H,订单明细!$I:$I,总体订单满足情况!I$2),"") | J12: =IFERROR(SUMIFS(订单明细!$K:$K,订单明细!$A:$A,总体订单满足情况!$H:$H,订单明细!$I:$I,总体订单满足情况!J$2)/SUMIFS(订单明细!$J:$J,订单明细!$A:$A,总体订单满足情况!$H:$H,订单明细!$I:$I,总体订单满足情况!J$2),"") | K12: =IFERROR(SUMIFS(订单明细!$K:$K,订单明细!$A:$A,总体订单满足情况!$H:$H,订单明细!$I:$I,总体订单满足情况!K$2)/SUMIFS(订单明细!$J:$J,订单明细!$A:$A,总体订单满足情况!$H:$H,订单明细!$I:$I,总体订单满足情况!K$2),"") | L12: =IFERROR(SUMIFS(订单明细!$K:$K,订单明细!$A:$A,总体订单满足情况!$H:$H,订单明细!$I:$I,总体订单满足情况!L$2)/SUMIFS(订单明细!$J:$J,订单明细!$A:$A,总体订单满足情况!$H:$H,订单明细!$I:$I,总体订单满足情况!L$2),"") | M12: =IFERROR(SUMIFS(订单明细!$K:$K,订单明细!$A:$A,总体订单满足情况!$H:$H,订单明细!$I:$I,总体订单满足情况!M$2)/SUMIFS(订单明细!$J:$J,订单明细!$A:$A,总体订单满足情况!$H:$H,订单明细!$I:$I,总体订单满足情况!M$2),"") | N12: =IFERROR(SUMIFS(订单明细!$K:$K,订单明细!$A:$A,总体订单满足情况!$H:$H,订单明细!$I:$I,总体订单满足情况!N$2)/SUMIFS(订单明细!$J:$J,订单明细!$A:$A,总体订单满足情况!$H:$H,订单明细!$I:$I,总体订单满足情况!N$2),"")
I13: =IFERROR(SUMIFS(订单明细!$K:$K,订单明细!$A:$A,总体订单满足情况!$H:$H,订单明细!$I:$I,总体订单满足情况!I$2)/SUMIFS(订单明细!$J:$J,订单明细!$A:$A,总体订单满足情况!$H:$H,订单明细!$I:$I,总体订单满足情况!I$2),"") | J13: =IFERROR(SUMIFS(订单明细!$K:$K,订单明细!$A:$A,总体订单满足情况!$H:$H,订单明细!$I:$I,总体订单满足情况!J$2)/SUMIFS(订单明细!$J:$J,订单明细!$A:$A,总体订单满足情况!$H:$H,订单明细!$I:$I,总体订单满足情况!J$2),"") | K13: =IFERROR(SUMIFS(订单明细!$K:$K,订单明细!$A:$A,总体订单满足情况!$H:$H,订单明细!$I:$I,总体订单满足情况!K$2)/SUMIFS(订单明细!$J:$J,订单明细!$A:$A,总体订单满足情况!$H:$H,订单明细!$I:$I,总体订单满足情况!K$2),"") | L13: =IFERROR(SUMIFS(订单明细!$K:$K,订单明细!$A:$A,总体订单满足情况!$H:$H,订单明细!$I:$I,总体订单满足情况!L$2)/SUMIFS(订单明细!$J:$J,订单明细!$A:$A,总体订单满足情况!$H:$H,订单明细!$I:$I,总体订单满足情况!L$2),"") | M13: =IFERROR(SUMIFS(订单明细!$K:$K,订单明细!$A:$A,总体订单满足情况!$H:$H,订单明细!$I:$I,总体订单满足情况!M$2)/SUMIFS(订单明细!$J:$J,订单明细!$A:$A,总体订单满足情况!$H:$H,订单明细!$I:$I,总体订单满足情况!M$2),"") | N13: =IFERROR(SUMIFS(订单明细!$K:$K,订单明细!$A:$A,总体订单满足情况!$H:$H,订单明细!$I:$I,总体订单满足情况!N$2)/SUMIFS(订单明细!$J:$J,订单明细!$A:$A,总体订单满足情况!$H:$H,订单明细!$I:$I,总体订单满足情况!N$2),"")
I14: =IFERROR(SUMIFS(订单明细!$K:$K,订单明细!$A:$A,总体订单满足情况!$H:$H,订单明细!$I:$I,总体订单满足情况!I$2)/SUMIFS(订单明细!$J:$J,订单明细!$A:$A,总体订单满足情况!$H:$H,订单明细!$I:$I,总体订单满足情况!I$2),"") | J14: =IFERROR(SUMIFS(订单明细!$K:$K,订单明细!$A:$A,总体订单满足情况!$H:$H,订单明细!$I:$I,总体订单满足情况!J$2)/SUMIFS(订单明细!$J:$J,订单明细!$A:$A,总体订单满足情况!$H:$H,订单明细!$I:$I,总体订单满足情况!J$2),"") | K14: =IFERROR(SUMIFS(订单明细!$K:$K,订单明细!$A:$A,总体订单满足情况!$H:$H,订单明细!$I:$I,总体订单满足情况!K$2)/SUMIFS(订单明细!$J:$J,订单明细!$A:$A,总体订单满足情况!$H:$H,订单明细!$I:$I,总体订单满足情况!K$2),"") | L14: =IFERROR(SUMIFS(订单明细!$K:$K,订单明细!$A:$A,总体订单满足情况!$H:$H,订单明细!$I:$I,总体订单满足情况!L$2)/SUMIFS(订单明细!$J:$J,订单明细!$A:$A,总体订单满足情况!$H:$H,订单明细!$I:$I,总体订单满足情况!L$2),"") | M14: =IFERROR(SUMIFS(订单明细!$K:$K,订单明细!$A:$A,总体订单满足情况!$H:$H,订单明细!$I:$I,总体订单满足情况!M$2)/SUMIFS(订单明细!$J:$J,订单明细!$A:$A,总体订单满足情况!$H:$H,订单明细!$I:$I,总体订单满足情况!M$2),"") | N14: =IFERROR(SUMIFS(订单明细!$K:$K,订单明细!$A:$A,总体订单满足情况!$H:$H,订单明细!$I:$I,总体订单满足情况!N$2)/SUMIFS(订单明细!$J:$J,订单明细!$A:$A,总体订单满足情况!$H:$H,订单明细!$I:$I,总体订单满足情况!N$2),"")
I15: =IFERROR(SUMIFS(订单明细!$K:$K,订单明细!$A:$A,总体订单满足情况!$H:$H,订单明细!$I:$I,总体订单满足情况!I$2)/SUMIFS(订单明细!$J:$J,订单明细!$A:$A,总体订单满足情况!$H:$H,订单明细!$I:$I,总体订单满足情况!I$2),"") | J15: =IFERROR(SUMIFS(订单明细!$K:$K,订单明细!$A:$A,总体订单满足情况!$H:$H,订单明细!$I:$I,总体订单满足情况!J$2)/SUMIFS(订单明细!$J:$J,订单明细!$A:$A,总体订单满足情况!$H:$H,订单明细!$I:$I,总体订单满足情况!J$2),"") | K15: =IFERROR(SUMIFS(订单明细!$K:$K,订单明细!$A:$A,总体订单满足情况!$H:$H,订单明细!$I:$I,总体订单满足情况!K$2)/SUMIFS(订单明细!$J:$J,订单明细!$A:$A,总体订单满足情况!$H:$H,订单明细!$I:$I,总体订单满足情况!K$2),"") | L15: =IFERROR(SUMIFS(订单明细!$K:$K,订单明细!$A:$A,总体订单满足情况!$H:$H,订单明细!$I:$I,总体订单满足情况!L$2)/SUMIFS(订单明细!$J:$J,订单明细!$A:$A,总体订单满足情况!$H:$H,订单明细!$I:$I,总体订单满足情况!L$2),"") | M15: =IFERROR(SUMIFS(订单明细!$K:$K,订单明细!$A:$A,总体订单满足情况!$H:$H,订单明细!$I:$I,总体订单满足情况!M$2)/SUMIFS(订单明细!$J:$J,订单明细!$A:$A,总体订单满足情况!$H:$H,订单明细!$I:$I,总体订单满足情况!M$2),"") | N15: =IFERROR(SUMIFS(订单明细!$K:$K,订单明细!$A:$A,总体订单满足情况!$H:$H,订单明细!$I:$I,总体订单满足情况!N$2)/SUMIFS(订单明细!$J:$J,订单明细!$A:$A,总体订单满足情况!$H:$H,订单明细!$I:$I,总体订单满足情况!N$2),"")
I16: =IFERROR(SUMIFS(订单明细!$K:$K,订单明细!$A:$A,总体订单满足情况!$H:$H,订单明细!$I:$I,总体订单满足情况!I$2)/SUMIFS(订单明细!$J:$J,订单明细!$A:$A,总体订单满足情况!$H:$H,订单明细!$I:$I,总体订单满足情况!I$2),"") | J16: =IFERROR(SUMIFS(订单明细!$K:$K,订单明细!$A:$A,总体订单满足情况!$H:$H,订单明细!$I:$I,总体订单满足情况!J$2)/SUMIFS(订单明细!$J:$J,订单明细!$A:$A,总体订单满足情况!$H:$H,订单明细!$I:$I,总体订单满足情况!J$2),"") | K16: =IFERROR(SUMIFS(订单明细!$K:$K,订单明细!$A:$A,总体订单满足情况!$H:$H,订单明细!$I:$I,总体订单满足情况!K$2)/SUMIFS(订单明细!$J:$J,订单明细!$A:$A,总体订单满足情况!$H:$H,订单明细!$I:$I,总体订单满足情况!K$2),"") | L16: =IFERROR(SUMIFS(订单明细!$K:$K,订单明细!$A:$A,总体订单满足情况!$H:$H,订单明细!$I:$I,总体订单满足情况!L$2)/SUMIFS(订单明细!$J:$J,订单明细!$A:$A,总体订单满足情况!$H:$H,订单明细!$I:$I,总体订单满足情况!L$2),"") | M16: =IFERROR(SUMIFS(订单明细!$K:$K,订单明细!$A:$A,总体订单满足情况!$H:$H,订单明细!$I:$I,总体订单满足情况!M$2)/SUMIFS(订单明细!$J:$J,订单明细!$A:$A,总体订单满足情况!$H:$H,订单明细!$I:$I,总体订单满足情况!M$2),"") | N16: =IFERROR(SUMIFS(订单明细!$K:$K,订单明细!$A:$A,总体订单满足情况!$H:$H,订单明细!$I:$I,总体订单满足情况!N$2)/SUMIFS(订单明细!$J:$J,订单明细!$A:$A,总体订单满足情况!$H:$H,订单明细!$I:$I,总体订单满足情况!N$2),"")
I17: =IFERROR(SUMIFS(订单明细!$K:$K,订单明细!$A:$A,总体订单满足情况!$H:$H,订单明细!$I:$I,总体订单满足情况!I$2)/SUMIFS(订单明细!$J:$J,订单明细!$A:$A,总体订单满足情况!$H:$H,订单明细!$I:$I,总体订单满足情况!I$2),"") | J17: =IFERROR(SUMIFS(订单明细!$K:$K,订单明细!$A:$A,总体订单满足情况!$H:$H,订单明细!$I:$I,总体订单满足情况!J$2)/SUMIFS(订单明细!$J:$J,订单明细!$A:$A,总体订单满足情况!$H:$H,订单明细!$I:$I,总体订单满足情况!J$2),"") | K17: =IFERROR(SUMIFS(订单明细!$K:$K,订单明细!$A:$A,总体订单满足情况!$H:$H,订单明细!$I:$I,总体订单满足情况!K$2)/SUMIFS(订单明细!$J:$J,订单明细!$A:$A,总体订单满足情况!$H:$H,订单明细!$I:$I,总体订单满足情况!K$2),"") | L17: =IFERROR(SUMIFS(订单明细!$K:$K,订单明细!$A:$A,总体订单满足情况!$H:$H,订单明细!$I:$I,总体订单满足情况!L$2)/SUMIFS(订单明细!$J:$J,订单明细!$A:$A,总体订单满足情况!$H:$H,订单明细!$I:$I,总体订单满足情况!L$2),"") | M17: =IFERROR(SUMIFS(订单明细!$K:$K,订单明细!$A:$A,总体订单满足情况!$H:$H,订单明细!$I:$I,总体订单满足情况!M$2)/SUMIFS(订单明细!$J:$J,订单明细!$A:$A,总体订单满足情况!$H:$H,订单明细!$I:$I,总体订单满足情况!M$2),"") | N17: =IFERROR(SUMIFS(订单明细!$K:$K,订单明细!$A:$A,总体订单满足情况!$H:$H,订单明细!$I:$I,总体订单满足情况!N$2)/SUMIFS(订单明细!$J:$J,订单明细!$A:$A,总体订单满足情况!$H:$H,订单明细!$I:$I,总体订单满足情况!N$2),"")
I18: =IFERROR(SUMIFS(订单明细!$K:$K,订单明细!$A:$A,总体订单满足情况!$H:$H,订单明细!$I:$I,总体订单满足情况!I$2)/SUMIFS(订单明细!$J:$J,订单明细!$A:$A,总体订单满足情况!$H:$H,订单明细!$I:$I,总体订单满足情况!I$2),"") | J18: =IFERROR(SUMIFS(订单明细!$K:$K,订单明细!$A:$A,总体订单满足情况!$H:$H,订单明细!$I:$I,总体订单满足情况!J$2)/SUMIFS(订单明细!$J:$J,订单明细!$A:$A,总体订单满足情况!$H:$H,订单明细!$I:$I,总体订单满足情况!J$2),"") | K18: =IFERROR(SUMIFS(订单明细!$K:$K,订单明细!$A:$A,总体订单满足情况!$H:$H,订单明细!$I:$I,总体订单满足情况!K$2)/SUMIFS(订单明细!$J:$J,订单明细!$A:$A,总体订单满足情况!$H:$H,订单明细!$I:$I,总体订单满足情况!K$2),"") | L18: =IFERROR(SUMIFS(订单明细!$K:$K,订单明细!$A:$A,总体订单满足情况!$H:$H,订单明细!$I:$I,总体订单满足情况!L$2)/SUMIFS(订单明细!$J:$J,订单明细!$A:$A,总体订单满足情况!$H:$H,订单明细!$I:$I,总体订单满足情况!L$2),"") | M18: =IFERROR(SUMIFS(订单明细!$K:$K,订单明细!$A:$A,总体订单满足情况!$H:$H,订单明细!$I:$I,总体订单满足情况!M$2)/SUMIFS(订单明细!$J:$J,订单明细!$A:$A,总体订单满足情况!$H:$H,订单明细!$I:$I,总体订单满足情况!M$2),"") | N18: =IFERROR(SUMIFS(订单明细!$K:$K,订单明细!$A:$A,总体订单满足情况!$H:$H,订单明细!$I:$I,总体订单满足情况!N$2)/SUMIFS(订单明细!$J:$J,订单明细!$A:$A,总体订单满足情况!$H:$H,订单明细!$I:$I,总体订单满足情况!N$2),"")
I19: =IFERROR(SUMIFS(订单明细!$K:$K,订单明细!$A:$A,总体订单满足情况!$H:$H,订单明细!$I:$I,总体订单满足情况!I$2)/SUMIFS(订单明细!$J:$J,订单明细!$A:$A,总体订单满足情况!$H:$H,订单明细!$I:$I,总体订单满足情况!I$2),"") | J19: =IFERROR(SUMIFS(订单明细!$K:$K,订单明细!$A:$A,总体订单满足情况!$H:$H,订单明细!$I:$I,总体订单满足情况!J$2)/SUMIFS(订单明细!$J:$J,订单明细!$A:$A,总体订单满足情况!$H:$H,订单明细!$I:$I,总体订单满足情况!J$2),"") | K19: =IFERROR(SUMIFS(订单明细!$K:$K,订单明细!$A:$A,总体订单满足情况!$H:$H,订单明细!$I:$I,总体订单满足情况!K$2)/SUMIFS(订单明细!$J:$J,订单明细!$A:$A,总体订单满足情况!$H:$H,订单明细!$I:$I,总体订单满足情况!K$2),"") | L19: =IFERROR(SUMIFS(订单明细!$K:$K,订单明细!$A:$A,总体订单满足情况!$H:$H,订单明细!$I:$I,总体订单满足情况!L$2)/SUMIFS(订单明细!$J:$J,订单明细!$A:$A,总体订单满足情况!$H:$H,订单明细!$I:$I,总体订单满足情况!L$2),"") | M19: =IFERROR(SUMIFS(订单明细!$K:$K,订单明细!$A:$A,总体订单满足情况!$H:$H,订单明细!$I:$I,总体订单满足情况!M$2)/SUMIFS(订单明细!$J:$J,订单明细!$A:$A,总体订单满足情况!$H:$H,订单明细!$I:$I,总体订单满足情况!M$2),"") | N19: =IFERROR(SUMIFS(订单明细!$K:$K,订单明细!$A:$A,总体订单满足情况!$H:$H,订单明细!$I:$I,总体订单满足情况!N$2)/SUMIFS(订单明细!$J:$J,订单明细!$A:$A,总体订单满足情况!$H:$H,订单明细!$I:$I,总体订单满足情况!N$2),"")
I20: =IFERROR(SUMIFS(订单明细!$K:$K,订单明细!$A:$A,总体订单满足情况!$H:$H,订单明细!$I:$I,总体订单满足情况!I$2)/SUMIFS(订单明细!$J:$J,订单明细!$A:$A,总体订单满足情况!$H:$H,订单明细!$I:$I,总体订单满足情况!I$2),"") | J20: =IFERROR(SUMIFS(订单明细!$K:$K,订单明细!$A:$A,总体订单满足情况!$H:$H,订单明细!$I:$I,总体订单满足情况!J$2)/SUMIFS(订单明细!$J:$J,订单明细!$A:$A,总体订单满足情况!$H:$H,订单明细!$I:$I,总体订单满足情况!J$2),"") | K20: =IFERROR(SUMIFS(订单明细!$K:$K,订单明细!$A:$A,总体订单满足情况!$H:$H,订单明细!$I:$I,总体订单满足情况!K$2)/SUMIFS(订单明细!$J:$J,订单明细!$A:$A,总体订单满足情况!$H:$H,订单明细!$I:$I,总体订单满足情况!K$2),"") | L20: =IFERROR(SUMIFS(订单明细!$K:$K,订单明细!$A:$A,总体订单满足情况!$H:$H,订单明细!$I:$I,总体订单满足情况!L$2)/SUMIFS(订单明细!$J:$J,订单明细!$A:$A,总体订单满足情况!$H:$H,订单明细!$I:$I,总体订单满足情况!L$2),"") | M20: =IFERROR(SUMIFS(订单明细!$K:$K,订单明细!$A:$A,总体订单满足情况!$H:$H,订单明细!$I:$I,总体订单满足情况!M$2)/SUMIFS(订单明细!$J:$J,订单明细!$A:$A,总体订单满足情况!$H:$H,订单明细!$I:$I,总体订单满足情况!M$2),"") | N20: =IFERROR(SUMIFS(订单明细!$K:$K,订单明细!$A:$A,总体订单满足情况!$H:$H,订单明细!$I:$I,总体订单满足情况!N$2)/SUMIFS(订单明细!$J:$J,订单明细!$A:$A,总体订单满足情况!$H:$H,订单明细!$I:$I,总体订单满足情况!N$2),"")
I21: =IFERROR(SUMIFS(订单明细!$K:$K,订单明细!$A:$A,总体订单满足情况!$H:$H,订单明细!$I:$I,总体订单满足情况!I$2)/SUMIFS(订单明细!$J:$J,订单明细!$A:$A,总体订单满足情况!$H:$H,订单明细!$I:$I,总体订单满足情况!I$2),"") | J21: =IFERROR(SUMIFS(订单明细!$K:$K,订单明细!$A:$A,总体订单满足情况!$H:$H,订单明细!$I:$I,总体订单满足情况!J$2)/SUMIFS(订单明细!$J:$J,订单明细!$A:$A,总体订单满足情况!$H:$H,订单明细!$I:$I,总体订单满足情况!J$2),"") | K21: =IFERROR(SUMIFS(订单明细!$K:$K,订单明细!$A:$A,总体订单满足情况!$H:$H,订单明细!$I:$I,总体订单满足情况!K$2)/SUMIFS(订单明细!$J:$J,订单明细!$A:$A,总体订单满足情况!$H:$H,订单明细!$I:$I,总体订单满足情况!K$2),"") | L21: =IFERROR(SUMIFS(订单明细!$K:$K,订单明细!$A:$A,总体订单满足情况!$H:$H,订单明细!$I:$I,总体订单满足情况!L$2)/SUMIFS(订单明细!$J:$J,订单明细!$A:$A,总体订单满足情况!$H:$H,订单明细!$I:$I,总体订单满足情况!L$2),"") | M21: =IFERROR(SUMIFS(订单明细!$K:$K,订单明细!$A:$A,总体订单满足情况!$H:$H,订单明细!$I:$I,总体订单满足情况!M$2)/SUMIFS(订单明细!$J:$J,订单明细!$A:$A,总体订单满足情况!$H:$H,订单明细!$I:$I,总体订单满足情况!M$2),"") | N21: =IFERROR(SUMIFS(订单明细!$K:$K,订单明细!$A:$A,总体订单满足情况!$H:$H,订单明细!$I:$I,总体订单满足情况!N$2)/SUMIFS(订单明细!$J:$J,订单明细!$A:$A,总体订单满足情况!$H:$H,订单明细!$I:$I,总体订单满足情况!N$2),"")
I22: =IFERROR(SUMIFS(订单明细!$K:$K,订单明细!$A:$A,总体订单满足情况!$H:$H,订单明细!$I:$I,总体订单满足情况!I$2)/SUMIFS(订单明细!$J:$J,订单明细!$A:$A,总体订单满足情况!$H:$H,订单明细!$I:$I,总体订单满足情况!I$2),"") | J22: =IFERROR(SUMIFS(订单明细!$K:$K,订单明细!$A:$A,总体订单满足情况!$H:$H,订单明细!$I:$I,总体订单满足情况!J$2)/SUMIFS(订单明细!$J:$J,订单明细!$A:$A,总体订单满足情况!$H:$H,订单明细!$I:$I,总体订单满足情况!J$2),"") | K22: =IFERROR(SUMIFS(订单明细!$K:$K,订单明细!$A:$A,总体订单满足情况!$H:$H,订单明细!$I:$I,总体订单满足情况!K$2)/SUMIFS(订单明细!$J:$J,订单明细!$A:$A,总体订单满足情况!$H:$H,订单明细!$I:$I,总体订单满足情况!K$2),"") | L22: =IFERROR(SUMIFS(订单明细!$K:$K,订单明细!$A:$A,总体订单满足情况!$H:$H,订单明细!$I:$I,总体订单满足情况!L$2)/SUMIFS(订单明细!$J:$J,订单明细!$A:$A,总体订单满足情况!$H:$H,订单明细!$I:$I,总体订单满足情况!L$2),"") | M22: =IFERROR(SUMIFS(订单明细!$K:$K,订单明细!$A:$A,总体订单满足情况!$H:$H,订单明细!$I:$I,总体订单满足情况!M$2)/SUMIFS(订单明细!$J:$J,订单明细!$A:$A,总体订单满足情况!$H:$H,订单明细!$I:$I,总体订单满足情况!M$2),"") | N22: =IFERROR(SUMIFS(订单明细!$K:$K,订单明细!$A:$A,总体订单满足情况!$H:$H,订单明细!$I:$I,总体订单满足情况!N$2)/SUMIFS(订单明细!$J:$J,订单明细!$A:$A,总体订单满足情况!$H:$H,订单明细!$I:$I,总体订单满足情况!N$2),"")

Sheet 日订单满足明细
A1: 华南RDC | M1: 西北RDC
A2: 日期 | B2: 渠道 | D2: 品牌 | M2: 日期 | N2: 渠道 | P2: 品牌
B3: 经销商 | C3: KA | D3: 六神 | E3: 美加净 | F3: 家安 | G3: 启初 | H3: 传统 | I3: 高夫 | J3: 片仔癀 | K3: 上海 | N3: 经销商 | O3: KA | P3: 六神 | Q3: 美加净 | R3: 家安 | S3: 启初 | T3: 传统 | U3: 高夫 | V3: 片仔癀 | W3: 上海
A4: 46266 | B4: =IFERROR(SUMIFS(订单明细!$K:$K,订单明细!$I:$I,日订单满足明细!$A$1,订单明细!$C:$C,日订单满足明细!$B$3,订单明细!$A:$A,日订单满足明细!$A4)/SUMIFS(订单明细!$J:$J,订单明细!$I:$I,日订单满足明细!$A$1,订单明细!$C:$C,日订单满足明细!$B$3,订单明细!$A:$A,日订单满足明细!$A4),"") -> 0.78790336 | C4: =IFERROR(SUMIFS(订单明细!$K:$K,订单明细!$I:$I,日订单满足明细!$A$1,订单明细!$C:$C,日订单满足明细!$C$3,订单明细!$A:$A,日订单满足明细!$A4)/SUMIFS(订单明细!$J:$J,订单明细!$I:$I,日订单满足明细!$A$1,订单明细!$C:$C,日订单满足明细!$C$3,订单明细!$A:$A,日订单满足明细!$A4),"") -> 0.90324223 | D4: =IFERROR(SUMIFS(订单明细!$K:$K,订单明细!$I:$I,$A$1,订单明细!$D:$D,日订单满足明细!D$3,订单明细!$A:$A,日订单满足明细!$A4)/SUMIFS(订单明细!$J:$J,订单明细!$I:$I,$A$1,订单明细!$D:$D,日订单满足明细!D$3,订单明细!$A:$A,日订单满足明细!$A4),"") -> 0.82890691 | E4: =IFERROR(SUMIFS(订单明细!$K:$K,订单明细!$I:$I,$A$1,订单明细!$D:$D,日订单满足明细!E$3,订单明细!$A:$A,日订单满足明细!$A4)/SUMIFS(订单明细!$J:$J,订单明细!$I:$I,$A$1,订单明细!$D:$D,日订单满足明细!E$3,订单明细!$A:$A,日订单满足明细!$A4),"") -> 1 | F4: =IFERROR(SUMIFS(订单明细!$K:$K,订单明细!$I:$I,$A$1,订单明细!$D:$D,日订单满足明细!F$3,订单明细!$A:$A,日订单满足明细!$A4)/SUMIFS(订单明细!$J:$J,订单明细!$I:$I,$A$1,订单明细!$D:$D,日订单满足明细!F$3,订单明细!$A:$A,日订单满足明细!$A4),"") -> 1 | G4: =IFERROR(SUMIFS(订单明细!$K:$K,订单明细!$I:$I,$A$1,订单明细!$D:$D,日订单满足明细!G$3,订单明细!$A:$A,日订单满足明细!$A4)/SUMIFS(订单明细!$J:$J,订单明细!$I:$I,$A$1,订单明细!$D:$D,日订单满足明细!G$3,订单明细!$A:$A,日订单满足明细!$A4),"") -> 0.91428571 | H4: =IFERROR(SUMIFS(订单明细!$K:$K,订单明细!$I:$I,$A$1,订单明细!$D:$D,日订单满足明细!H$3,订单明细!$A:$A,日订单满足明细!$A4)/SUMIFS(订单明细!$J:$J,订单明细!$I:$I,$A$1,订单明细!$D:$D,日订单满足明细!H$3,订单明细!$A:$A,日订单满足明细!$A4),"") | I4: =IFERROR(SUMIFS(订单明细!$K:$K,订单明细!$I:$I,$A$1,订单明细!$D:$D,日订单满足明细!I$3,订单明细!$A:$A,日订单满足明细!$A4)/SUMIFS(订单明细!$J:$J,订单明细!$I:$I,$A$1,订单明细!$D:$D,日订单满足明细!I$3,订单明细!$A:$A,日订单满足明细!$A4),"") | J4: =IFERROR(SUMIFS(订单明细!$K:$K,订单明细!$I:$I,$A$1,订单明细!$D:$D,日订单满足明细!J$3,订单明细!$A:$A,日订单满足明细!$A4)/SUMIFS(订单明细!$J:$J,订单明细!$I:$I,$A$1,订单明细!$D:$D,日订单满足明细!J$3,订单明细!$A:$A,日订单满足明细!$A4),"") | K4: =IFERROR(SUMIFS(订单明细!$K:$K,订单明细!$I:$I,$A$1,订单明细!$D:$D,日订单满足明细!K$3,订单明细!$A:$A,日订单满足明细!$A4)/SUMIFS(订单明细!$J:$J,订单明细!$I:$I,$A$1,订单明细!$D:$D,日订单满足明细!K$3,订单明细!$A:$A,日订单满足明细!$A4),"") -> 1 | M4: 46266 | N4: =IFERROR(SUMIFS(订单明细!$K:$K,订单明细!$I:$I,$M$1,订单明细!$C:$C,日订单满足明细!$N$3,订单明细!$A:$A,日订单满足明细!$A4)/SUMIFS(订单明细!$J:$J,订单明细!$I:$I,$M$1,订单明细!$C:$C,日订单满足明细!$N$3,订单明细!$A:$A,日订单满足明细!$A4),"") -> 0.89417323 | O4: =IFERROR(SUMIFS(订单明细!$K:$K,订单明细!$I:$I,$M$1,订单明细!$C:$C,日订单满足明细!$O$3,订单明细!$A:$A,日订单满足明细!$A4)/SUMIFS(订单明细!$J:$J,订单明细!$I:$I,$M$1,订单明细!$C:$C,日订单满足明细!$O$3,订单明细!$A:$A,日订单满足明细!$A4),"") -> 0.98830409 | P4: =IFERROR(SUMIFS(订单明细!$K:$K,订单明细!$I:$I,$M$1,订单明细!$D:$D,日订单满足明细!P$3,订单明细!$A:$A,日订单满足明细!$A4)/SUMIFS(订单明细!$J:$J,订单明细!$I:$I,$M$1,订单明细!$D:$D,日订单满足明细!P$3,订单明细!$A:$A,日订单满足明细!$A4),"") -> 0.99583767 | Q4: =IFERROR(SUMIFS(订单明细!$K:$K,订单明细!$I:$I,$M$1,订单明细!$D:$D,日订单满足明细!Q$3,订单明细!$A:$A,日订单满足明细!$A4)/SUMIFS(订单明细!$J:$J,订单明细!$I:$I,$M$1,订单明细!$D:$D,日订单满足明细!Q$3,订单明细!$A:$A,日订单满足明细!$A4),"") -> 1 | R4: =IFERROR(SUMIFS(订单明细!$K:$K,订单明细!$I:$I,$M$1,订单明细!$D:$D,日订单满足明细!R$3,订单明细!$A:$A,日订单满足明细!$A4)/SUMIFS(订单明细!$J:$J,订单明细!$I:$I,$M$1,订单明细!$D:$D,日订单满足明细!R$3,订单明细!$A:$A,日订单满足明细!$A4),"") -> 1 | S4: =IFERROR(SUMIFS(订单明细!$K:$K,订单明细!$I:$I,$M$1,订单明细!$D:$D,日订单满足明细!S$3,订单明细!$A:$A,日订单满足明细!$A4)/SUMIFS(订单明细!$J:$J,订单明细!$I:$I,$M$1,订单明细!$D:$D,日订单满足明细!S$3,订单明细!$A:$A,日订单满足明细!$A4),"") -> 1 | T4: =IFERROR(SUMIFS(订单明细!$K:$K,订单明细!$I:$I,$M$1,订单明细!$D:$D,日订单满足明细!T$3,订单明细!$A:$A,日订单满足明细!$A4)/SUMIFS(订单明细!$J:$J,订单明细!$I:$I,$M$1,订单明细!$D:$D,日订单满足明细!T$3,订单明细!$A:$A,日订单满足明细!$A4),"") | U4: =IFERROR(SUMIFS(订单明细!$K:$K,订单明细!$I:$I,$M$1,订单明细!$D:$D,日订单满足明细!U$3,订单明细!$A:$A,日订单满足明细!$A4)/SUMIFS(订单明细!$J:$J,订单明细!$I:$I,$M$1,订单明细!$D:$D,日订单满足明细!U$3,订单明细!$A:$A,日订单满足明细!$A4),"") -> 0.52742616 | V4: =IFERROR(SUMIFS(订单明细!$K:$K,订单明细!$I:$I,$M$1,订单明细!$D:$D,日订单满足明细!V$3,订单明细!$A:$A,日订单满足明细!$A4)/SUMIFS(订单明细!$J:$J,订单明细!$I:$I,$M$1,订单明细!$D:$D,日订单满足明细!V$3,订单明细!$A:$A,日订单满足明细!$A4),"") | W4: =IFERROR(SUMIFS(订单明细!$K:$K,订单明细!$I:$I,$M$1,订单明细!$D:$D,日订单满足明细!W$3,订单明细!$A:$A,日订单满足明细!$A4)/SUMIFS(订单明细!$J:$J,订单明细!$I:$I,$M$1,订单明细!$D:$D,日订单满足明细!W$3,订单明细!$A:$A,日订单满足明细!$A4),"") -> 1
A5: 46267 | B5: =IFERROR(SUMIFS(订单明细!$K:$K,订单明细!$I:$I,日订单满足明细!$A$1,订单明细!$C:$C,日订单满足明细!$B$3,订单明细!$A:$A,日订单满足明细!$A5)/SUMIFS(订单明细!$J:$J,订单明细!$I:$I,日订单满足明细!$A$1,订单明细!$C:$C,日订单满足明细!$B$3,订单明细!$A:$A,日订单满足明细!$A5),"") -> 0.96559414 | C5: =IFERROR(SUMIFS(订单明细!$K:$K,订单明细!$I:$I,日订单满足明细!$A$1,订单明细!$C:$C,日订单满足明细!$C$3,订单明细!$A:$A,日订单满足明细!$A5)/SUMIFS(订单明细!$J:$J,订单明细!$I:$I,日订单满足明细!$A$1,订单明细!$C:$C,日订单满足明细!$C$3,订单明细!$A:$A,日订单满足明细!$A5),"") -> 0.70658683 | D5: =IFERROR(SUMIFS(订单明细!$K:$K,订单明细!$I:$I,$A$1,订单明细!$D:$D,日订单满足明细!D$3,订单明细!$A:$A,日订单满足明细!$A5)/SUMIFS(订单明细!$J:$J,订单明细!$I:$I,$A$1,订单明细!$D:$D,日订单满足明细!D$3,订单明细!$A:$A,日订单满足明细!$A5),"") -> 0.9622194 | E5: =IFERROR(SUMIFS(订单明细!$K:$K,订单明细!$I:$I,$A$1,订单明细!$D:$D,日订单满足明细!E$3,订单明细!$A:$A,日订单满足明细!$A5)/SUMIFS(订单明细!$J:$J,订单明细!$I:$I,$A$1,订单明细!$D:$D,日订单满足明细!E$3,订单明细!$A:$A,日订单满足明细!$A5),"") -> 1 | F5: =IFERROR(SUMIFS(订单明细!$K:$K,订单明细!$I:$I,$A$1,订单明细!$D:$D,日订单满足明细!F$3,订单明细!$A:$A,日订单满足明细!$A5)/SUMIFS(订单明细!$J:$J,订单明细!$I:$I,$A$1,订单明细!$D:$D,日订单满足明细!F$3,订单明细!$A:$A,日订单满足明细!$A5),"") -> 1 | G5: =IFERROR(SUMIFS(订单明细!$K:$K,订单明细!$I:$I,$A$1,订单明细!$D:$D,日订单满足明细!G$3,订单明细!$A:$A,日订单满足明细!$A5)/SUMIFS(订单明细!$J:$J,订单明细!$I:$I,$A$1,订单明细!$D:$D,日订单满足明细!G$3,订单明细!$A:$A,日订单满足明细!$A5),"") -> 0.56701031 | H5: =IFERROR(SUMIFS(订单明细!$K:$K,订单明细!$I:$I,$A$1,订单明细!$D:$D,日订单满足明细!H$3,订单明细!$A:$A,日订单满足明细!$A5)/SUMIFS(订单明细!$J:$J,订单明细!$I:$I,$A$1,订单明细!$D:$D,日订单满足明细!H$3,订单明细!$A:$A,日订单满足明细!$A5),"") | I5: =IFERROR(SUMIFS(订单明细!$K:$K,订单明细!$I:$I,$A$1,订单明细!$D:$D,日订单满足明细!I$3,订单明细!$A:$A,日订单满足明细!$A5)/SUMIFS(订单明细!$J:$J,订单明细!$I:$I,$A$1,订单明细!$D:$D,日订单满足明细!I$3,订单明细!$A:$A,日订单满足明细!$A5),"") | J5: =IFERROR(SUMIFS(订单明细!$K:$K,订单明细!$I:$I,$A$1,订单明细!$D:$D,日订单满足明细!J$3,订单明细!$A:$A,日订单满足明细!$A5)/SUMIFS(订单明细!$J:$J,订单明细!$I:$I,$A$1,订单明细!$D:$D,日订单满足明细!J$3,订单明细!$A:$A,日订单满足明细!$A5),"") | K5: =IFERROR(SUMIFS(订单明细!$K:$K,订单明细!$I:$I,$A$1,订单明细!$D:$D,日订单满足明细!K$3,订单明细!$A:$A,日订单满足明细!$A5)/SUMIFS(订单明细!$J:$J,订单明细!$I:$I,$A$1,订单明细!$D:$D,日订单满足明细!K$3,订单明细!$A:$A,日订单满足明细!$A5),"") -> 1 | M5: 46267 | N5: =IFERROR(SUMIFS(订单明细!$K:$K,订单明细!$I:$I,$M$1,订单明细!$C:$C,日订单满足明细!$N$3,订单明细!$A:$A,日订单满足明细!$A5)/SUMIFS(订单明细!$J:$J,订单明细!$I:$I,$M$1,订单明细!$C:$C,日订单满足明细!$N$3,订单明细!$A:$A,日订单满足明细!$A5),"") -> 0.96316832 | O5: =IFERROR(SUMIFS(订单明细!$K:$K,订单明细!$I:$I,$M$1,订单明细!$C:$C,日订单满足明细!$O$3,订单明细!$A:$A,日订单满足明细!$A5)/SUMIFS(订单明细!$J:$J,订单明细!$I:$I,$M$1,订单明细!$C:$C,日订单满足明细!$O$3,订单明细!$A:$A,日订单满足明细!$A5),"") -> 0.88235294 | P5: =IFERROR(SUMIFS(订单明细!$K:$K,订单明细!$I:$I,$M$1,订单明细!$D:$D,日订单满足明细!P$3,订单明细!$A:$A,日订单满足明细!$A5)/SUMIFS(订单明细!$J:$J,订单明细!$I:$I,$M$1,订单明细!$D:$D,日订单满足明细!P$3,订单明细!$A:$A,日订单满足明细!$A5),"") -> 0.94333333 | Q5: =IFERROR(SUMIFS(订单明细!$K:$K,订单明细!$I:$I,$M$1,订单明细!$D:$D,日订单满足明细!Q$3,订单明细!$A:$A,日订单满足明细!$A5)/SUMIFS(订单明细!$J:$J,订单明细!$I:$I,$M$1,订单明细!$D:$D,日订单满足明细!Q$3,订单明细!$A:$A,日订单满足明细!$A5),"") -> 0.99534161 | R5: =IFERROR(SUMIFS(订单明细!$K:$K,订单明细!$I:$I,$M$1,订单明细!$D:$D,日订单满足明细!R$3,订单明细!$A:$A,日订单满足明细!$A5)/SUMIFS(订单明细!$J:$J,订单明细!$I:$I,$M$1,订单明细!$D:$D,日订单满足明细!R$3,订单明细!$A:$A,日订单满足明细!$A5),"") -> 1 | S5: =IFERROR(SUMIFS(订单明细!$K:$K,订单明细!$I:$I,$M$1,订单明细!$D:$D,日订单满足明细!S$3,订单明细!$A:$A,日订单满足明细!$A5)/SUMIFS(订单明细!$J:$J,订单明细!$I:$I,$M$1,订单明细!$D:$D,日订单满足明细!S$3,订单明细!$A:$A,日订单满足明细!$A5),"") -> 1 | T5: =IFERROR(SUMIFS(订单明细!$K:$K,订单明细!$I:$I,$M$1,订单明细!$D:$D,日订单满足明细!T$3,订单明细!$A:$A,日订单满足明细!$A5)/SUMIFS(订单明细!$J:$J,订单明细!$I:$I,$M$1,订单明细!$D:$D,日订单满足明细!T$3,订单明细!$A:$A,日订单满足明细!$A5),"") | U5: =IFERROR(SUMIFS(订单明细!$K:$K,订单明细!$I:$I,$M$1,订单明细!$D:$D,日订单满足明细!U$3,订单明细!$A:$A,日订单满足明细!$A5)/SUMIFS(订单明细!$J:$J,订单明细!$I:$I,$M$1,订单明细!$D:$D,日订单满足明细!U$3,订单明细!$A:$A,日订单满足明细!$A5),"") -> 0.69565217 | V5: =IFERROR(SUMIFS(订单明细!$K:$K,订单明细!$I:$I,$M$1,订单明细!$D:$D,日订单满足明细!V$3,订单明细!$A:$A,日订单满足明细!$A5)/SUMIFS(订单明细!$J:$J,订单明细!$I:$I,$M$1,订单明细!$D:$D,日订单满足明细!V$3,订单明细!$A:$A,日订单满足明细!$A5),"") | W5: =IFERROR(SUMIFS(订单明细!$K:$K,订单明细!$I:$I,$M$1,订单明细!$D:$D,日订单满足明细!W$3,订单明细!$A:$A,日订单满足明细!$A5)/SUMIFS(订单明细!$J:$J,订单明细!$I:$I,$M$1,订单明细!$D:$D,日订单满足明细!W$3,订单明细!$A:$A,日订单满足明细!$A5),"")
A6: 46268 | B6: =IFERROR(SUMIFS(订单明细!$K:$K,订单明细!$I:$I,日订单满足明细!$A$1,订单明细!$C:$C,日订单满足明细!$B$3,订单明细!$A:$A,日订单满足明细!$A6)/SUMIFS(订单明细!$J:$J,订单明细!$I:$I,日订单满足明细!$A$1,订单明细!$C:$C,日订单满足明细!$B$3,订单明细!$A:$A,日订单满足明细!$A6),"") -> 0.86553925 | C6: =IFERROR(SUMIFS(订单明细!$K:$K,订单明细!$I:$I,日订单满足明细!$A$1,订单明细!$C:$C,日订单满足明细!$C$3,订单明细!$A:$A,日订单满足明细!$A6)/SUMIFS(订单明细!$J:$J,订单明细!$I:$I,日订单满足明细!$A$1,订单明细!$C:$C,日订单满足明细!$C$3,订单明细!$A:$A,日订单满足明细!$A6),"") -> 0.8968347 | D6: =IFERROR(SUMIFS(订单明细!$K:$K,订单明细!$I:$I,$A$1,订单明细!$D:$D,日订单满足明细!D$3,订单明细!$A:$A,日订单满足明细!$A6)/SUMIFS(订单明细!$J:$J,订单明细!$I:$I,$A$1,订单明细!$D:$D,日订单满足明细!D$3,订单明细!$A:$A,日订单满足明细!$A6),"") -> 0.90180803 | E6: =IFERROR(SUMIFS(订单明细!$K:$K,订单明细!$I:$I,$A$1,订单明细!$D:$D,日订单满足明细!E$3,订单明细!$A:$A,日订单满足明细!$A6)/SUMIFS(订单明细!$J:$J,订单明细!$I:$I,$A$1,订单明细!$D:$D,日订单满足明细!E$3,订单明细!$A:$A,日订单满足明细!$A6),"") -> 0.95430022 | F6: =IFERROR(SUMIFS(订单明细!$K:$K,订单明细!$I:$I,$A$1,订单明细!$D:$D,日订单满足明细!F$3,订单明细!$A:$A,日订单满足明细!$A6)/SUMIFS(订单明细!$J:$J,订单明细!$I:$I,$A$1,订单明细!$D:$D,日订单满足明细!F$3,订单明细!$A:$A,日订单满足明细!$A6),"") -> 1 | G6: =IFERROR(SUMIFS(订单明细!$K:$K,订单明细!$I:$I,$A$1,订单明细!$D:$D,日订单满足明细!G$3,订单明细!$A:$A,日订单满足明细!$A6)/SUMIFS(订单明细!$J:$J,订单明细!$I:$I,$A$1,订单明细!$D:$D,日订单满足明细!G$3,订单明细!$A:$A,日订单满足明细!$A6),"") -> 0.73333333 | H6: =IFERROR(SUMIFS(订单明细!$K:$K,订单明细!$I:$I,$A$1,订单明细!$D:$D,日订单满足明细!H$3,订单明细!$A:$A,日订单满足明细!$A6)/SUMIFS(订单明细!$J:$J,订单明细!$I:$I,$A$1,订单明细!$D:$D,日订单满足明细!H$3,订单明细!$A:$A,日订单满足明细!$A6),"") | I6: =IFERROR(SUMIFS(订单明细!$K:$K,订单明细!$I:$I,$A$1,订单明细!$D:$D,日订单满足明细!I$3,订单明细!$A:$A,日订单满足明细!$A6)/SUMIFS(订单明细!$J:$J,订单明细!$I:$I,$A$1,订单明细!$D:$D,日订单满足明细!I$3,订单明细!$A:$A,日订单满足明细!$A6),"") | J6: =IFERROR(SUMIFS(订单明细!$K:$K,订单明细!$I:$I,$A$1,订单明细!$D:$D,日订单满足明细!J$3,订单明细!$A:$A,日订单满足明细!$A6)/SUMIFS(订单明细!$J:$J,订单明细!$I:$I,$A$1,订单明细!$D:$D,日订单满足明细!J$3,订单明细!$A:$A,日订单满足明细!$A6),"") | K6: =IFERROR(SUMIFS(订单明细!$K:$K,订单明细!$I:$I,$A$1,订单明细!$D:$D,日订单满足明细!K$3,订单明细!$A:$A,日订单满足明细!$A6)/SUMIFS(订单明细!$J:$J,订单明细!$I:$I,$A$1,订单明细!$D:$D,日订单满足明细!K$3,订单明细!$A:$A,日订单满足明细!$A6),"") | M6: 46268 | N6: =IFERROR(SUMIFS(订单明细!$K:$K,订单明细!$I:$I,$M$1,订单明细!$C:$C,日订单满足明细!$N$3,订单明细!$A:$A,日订单满足明细!$A6)/SUMIFS(订单明细!$J:$J,订单明细!$I:$I,$M$1,订单明细!$C:$C,日订单满足明细!$N$3,订单明细!$A:$A,日订单满足明细!$A6),"") -> 1 | O6: =IFERROR(SUMIFS(订单明细!$K:$K,订单明细!$I:$I,$M$1,订单明细!$C:$C,日订单满足明细!$O$3,订单明细!$A:$A,日订单满足明细!$A6)/SUMIFS(订单明细!$J:$J,订单明细!$I:$I,$M$1,订单明细!$C:$C,日订单满足明细!$O$3,订单明细!$A:$A,日订单满足明细!$A6),"") -> 0.82222222 | P6: =IFERROR(SUMIFS(订单明细!$K:$K,订单明细!$I:$I,$M$1,订单明细!$D:$D,日订单满足明细!P$3,订单明细!$A:$A,日订单满足明细!$A6)/SUMIFS(订单明细!$J:$J,订单明细!$I:$I,$M$1,订单明细!$D:$D,日订单满足明细!P$3,订单明细!$A:$A,日订单满足明细!$A6),"") -> 0.94630872 | Q6: =IFERROR(SUMIFS(订单明细!$K:$K,订单明细!$I:$I,$M$1,订单明细!$D:$D,日订单满足明细!Q$3,订单明细!$A:$A,日订单满足明细!$A6)/SUMIFS(订单明细!$J:$J,订单明细!$I:$I,$M$1,订单明细!$D:$D,日订单满足明细!Q$3,订单明细!$A:$A,日订单满足明细!$A6),"") -> 1 | R6: =IFERROR(SUMIFS(订单明细!$K:$K,订单明细!$I:$I,$M$1,订单明细!$D:$D,日订单满足明细!R$3,订单明细!$A:$A,日订单满足明细!$A6)/SUMIFS(订单明细!$J:$J,订单明细!$I:$I,$M$1,订单明细!$D:$D,日订单满足明细!R$3,订单明细!$A:$A,日订单满足明细!$A6),"") | S6: =IFERROR(SUMIFS(订单明细!$K:$K,订单明细!$I:$I,$M$1,订单明细!$D:$D,日订单满足明细!S$3,订单明细!$A:$A,日订单满足明细!$A6)/SUMIFS(订单明细!$J:$J,订单明细!$I:$I,$M$1,订单明细!$D:$D,日订单满足明细!S$3,订单明细!$A:$A,日订单满足明细!$A6),"") -> 1 | T6: =IFERROR(SUMIFS(订单明细!$K:$K,订单明细!$I:$I,$M$1,订单明细!$D:$D,日订单满足明细!T$3,订单明细!$A:$A,日订单满足明细!$A6)/SUMIFS(订单明细!$J:$J,订单明细!$I:$I,$M$1,订单明细!$D:$D,日订单满足明细!T$3,订单明细!$A:$A,日订单满足明细!$A6),"") | U6: =IFERROR(SUMIFS(订单明细!$K:$K,订单明细!$I:$I,$M$1,订单明细!$D:$D,日订单满足明细!U$3,订单明细!$A:$A,日订单满足明细!$A6)/SUMIFS(订单明细!$J:$J,订单明细!$I:$I,$M$1,订单明细!$D:$D,日订单满足明细!U$3,订单明细!$A:$A,日订单满足明细!$A6),"") | V6: =IFERROR(SUMIFS(订单明细!$K:$K,订单明细!$I:$I,$M$1,订单明细!$D:$D,日订单满足明细!V$3,订单明细!$A:$A,日订单满足明细!$A6)/SUMIFS(订单明细!$J:$J,订单明细!$I:$I,$M$1,订单明细!$D:$D,日订单满足明细!V$3,订单明细!$A:$A,日订单满足明细!$A6),"") | W6: =IFERROR(SUMIFS(订单明细!$K:$K,订单明细!$I:$I,$M$1,订单明细!$D:$D,日订单满足明细!W$3,订单明细!$A:$A,日订单满足明细!$A6)/SUMIFS(订单明细!$J:$J,订单明细!$I:$I,$M$1,订单明细!$D:$D,日订单满足明细!W$3,订单明细!$A:$A,日订单满足明细!$A6),"")
A7: 46269 | B7: =IFERROR(SUMIFS(订单明细!$K:$K,订单明细!$I:$I,日订单满足明细!$A$1,订单明细!$C:$C,日订单满足明细!$B$3,订单明细!$A:$A,日订单满足明细!$A7)/SUMIFS(订单明细!$J:$J,订单明细!$I:$I,日订单满足明细!$A$1,订单明细!$C:$C,日订单满足明细!$B$3,订单明细!$A:$A,日订单满足明细!$A7),"") -> 0.9564339 | C7: =IFERROR(SUMIFS(订单明细!$K:$K,订单明细!$I:$I,日订单满足明细!$A$1,订单明细!$C:$C,日订单满足明细!$C$3,订单明细!$A:$A,日订单满足明细!$A7)/SUMIFS(订单明细!$J:$J,订单明细!$I:$I,日订单满足明细!$A$1,订单明细!$C:$C,日订单满足明细!$C$3,订单明细!$A:$A,日订单满足明细!$A7),"") -> 0.98293912 | D7: =IFERROR(SUMIFS(订单明细!$K:$K,订单明细!$I:$I,$A$1,订单明细!$D:$D,日订单满足明细!D$3,订单明细!$A:$A,日订单满足明细!$A7)/SUMIFS(订单明细!$J:$J,订单明细!$I:$I,$A$1,订单明细!$D:$D,日订单满足明细!D$3,订单明细!$A:$A,日订单满足明细!$A7),"") -> 0.93781263 | E7: =IFERROR(SUMIFS(订单明细!$K:$K,订单明细!$I:$I,$A$1,订单明细!$D:$D,日订单满足明细!E$3,订单明细!$A:$A,日订单满足明细!$A7)/SUMIFS(订单明细!$J:$J,订单明细!$I:$I,$A$1,订单明细!$D:$D,日订单满足明细!E$3,订单明细!$A:$A,日订单满足明细!$A7),"") -> 0.98239609 | F7: =IFERROR(SUMIFS(订单明细!$K:$K,订单明细!$I:$I,$A$1,订单明细!$D:$D,日订单满足明细!F$3,订单明细!$A:$A,日订单满足明细!$A7)/SUMIFS(订单明细!$J:$J,订单明细!$I:$I,$A$1,订单明细!$D:$D,日订单满足明细!F$3,订单明细!$A:$A,日订单满足明细!$A7),"") -> 1 | G7: =IFERROR(SUMIFS(订单明细!$K:$K,订单明细!$I:$I,$A$1,订单明细!$D:$D,日订单满足明细!G$3,订单明细!$A:$A,日订单满足明细!$A7)/SUMIFS(订单明细!$J:$J,订单明细!$I:$I,$A$1,订单明细!$D:$D,日订单满足明细!G$3,订单明细!$A:$A,日订单满足明细!$A7),"") -> 0.76595745 | H7: =IFERROR(SUMIFS(订单明细!$K:$K,订单明细!$I:$I,$A$1,订单明细!$D:$D,日订单满足明细!H$3,订单明细!$A:$A,日订单满足明细!$A7)/SUMIFS(订单明细!$J:$J,订单明细!$I:$I,$A$1,订单明细!$D:$D,日订单满足明细!H$3,订单明细!$A:$A,日订单满足明细!$A7),"") | I7: =IFERROR(SUMIFS(订单明细!$K:$K,订单明细!$I:$I,$A$1,订单明细!$D:$D,日订单满足明细!I$3,订单明细!$A:$A,日订单满足明细!$A7)/SUMIFS(订单明细!$J:$J,订单明细!$I:$I,$A$1,订单明细!$D:$D,日订单满足明细!I$3,订单明细!$A:$A,日订单满足明细!$A7),"") | J7: =IFERROR(SUMIFS(订单明细!$K:$K,订单明细!$I:$I,$A$1,订单明细!$D:$D,日订单满足明细!J$3,订单明细!$A:$A,日订单满足明细!$A7)/SUMIFS(订单明细!$J:$J,订单明细!$I:$I,$A$1,订单明细!$D:$D,日订单满足明细!J$3,订单明细!$A:$A,日订单满足明细!$A7),"") | K7: =IFERROR(SUMIFS(订单明细!$K:$K,订单明细!$I:$I,$A$1,订单明细!$D:$D,日订单满足明细!K$3,订单明细!$A:$A,日订单满足明细!$A7)/SUMIFS(订单明细!$J:$J,订单明细!$I:$I,$A$1,订单明细!$D:$D,日订单满足明细!K$3,订单明细!$A:$A,日订单满足明细!$A7),"") -> 1 | M7: 46269 | N7: =IFERROR(SUMIFS(订单明细!$K:$K,订单明细!$I:$I,$M$1,订单明细!$C:$C,日订单满足明细!$N$3,订单明细!$A:$A,日订单满足明细!$A7)/SUMIFS(订单明细!$J:$J,订单明细!$I:$I,$M$1,订单明细!$C:$C,日订单满足明细!$N$3,订单明细!$A:$A,日订单满足明细!$A7),"") -> 0.64119882 | O7: =IFERROR(SUMIFS(订单明细!$K:$K,订单明细!$I:$I,$M$1,订单明细!$C:$C,日订单满足明细!$O$3,订单明细!$A:$A,日订单满足明细!$A7)/SUMIFS(订单明细!$J:$J,订单明细!$I:$I,$M$1,订单明细!$C:$C,日订单满足明细!$O$3,订单明细!$A:$A,日订单满足明细!$A7),"") -> 0.92550143 | P7: =IFERROR(SUMIFS(订单明细!$K:$K,订单明细!$I:$I,$M$1,订单明细!$D:$D,日订单满足明细!P$3,订单明细!$A:$A,日订单满足明细!$A7)/SUMIFS(订单明细!$J:$J,订单明细!$I:$I,$M$1,订单明细!$D:$D,日订单满足明细!P$3,订单明细!$A:$A,日订单满足明细!$A7),"") -> 0.92571012 | Q7: =IFERROR(SUMIFS(订单明细!$K:$K,订单明细!$I:$I,$M$1,订单明细!$D:$D,日订单满足明细!Q$3,订单明细!$A:$A,日订单满足明细!$A7)/SUMIFS(订单明细!$J:$J,订单明细!$I:$I,$M$1,订单明细!$D:$D,日订单满足明细!Q$3,订单明细!$A:$A,日订单满足明细!$A7),"") -> 0.38356164 | R7: =IFERROR(SUMIFS(订单明细!$K:$K,订单明细!$I:$I,$M$1,订单明细!$D:$D,日订单满足明细!R$3,订单明细!$A:$A,日订单满足明细!$A7)/SUMIFS(订单明细!$J:$J,订单明细!$I:$I,$M$1,订单明细!$D:$D,日订单满足明细!R$3,订单明细!$A:$A,日订单满足明细!$A7),"") -> 0.2173913 | S7: =IFERROR(SUMIFS(订单明细!$K:$K,订单明细!$I:$I,$M$1,订单明细!$D:$D,日订单满足明细!S$3,订单明细!$A:$A,日订单满足明细!$A7)/SUMIFS(订单明细!$J:$J,订单明细!$I:$I,$M$1,订单明细!$D:$D,日订单满足明细!S$3,订单明细!$A:$A,日订单满足明细!$A7),"") -> 1 | T7: =IFERROR(SUMIFS(订单明细!$K:$K,订单明细!$I:$I,$M$1,订单明细!$D:$D,日订单满足明细!T$3,订单明细!$A:$A,日订单满足明细!$A7)/SUMIFS(订单明细!$J:$J,订单明细!$I:$I,$M$1,订单明细!$D:$D,日订单满足明细!T$3,订单明细!$A:$A,日订单满足明细!$A7),"") | U7: =IFERROR(SUMIFS(订单明细!$K:$K,订单明细!$I:$I,$M$1,订单明细!$D:$D,日订单满足明细!U$3,订单明细!$A:$A,日订单满足明细!$A7)/SUMIFS(订单明细!$J:$J,订单明细!$I:$I,$M$1,订单明细!$D:$D,日订单满足明细!U$3,订单明细!$A:$A,日订单满足明细!$A7),"") -> 1 | V7: =IFERROR(SUMIFS(订单明细!$K:$K,订单明细!$I:$I,$M$1,订单明细!$D:$D,日订单满足明细!V$3,订单明细!$A:$A,日订单满足明细!$A7)/SUMIFS(订单明细!$J:$J,订单明细!$I:$I,$M$1,订单明细!$D:$D,日订单满足明细!V$3,订单明细!$A:$A,日订单满足明细!$A7),"") | W7: =IFERROR(SUMIFS(订单明细!$K:$K,订单明细!$I:$I,$M$1,订单明细!$D:$D,日订单满足明细!W$3,订单明细!$A:$A,日订单满足明细!$A7)/SUMIFS(订单明细!$J:$J,订单明细!$I:$I,$M$1,订单明细!$D:$D,日订单满足明细!W$3,订单明细!$A:$A,日订单满足明细!$A7),"")
A8: 46272 | B8: =IFERROR(SUMIFS(订单明细!$K:$K,订单明细!$I:$I,日订单满足明细!$A$1,订单明细!$C:$C,日订单满足明细!$B$3,订单明细!$A:$A,日订单满足明细!$A8)/SUMIFS(订单明细!$J:$J,订单明细!$I:$I,日订单满足明细!$A$1,订单明细!$C:$C,日订单满足明细!$B$3,订单明细!$A:$A,日订单满足明细!$A8),"") -> 0.94909578 | C8: =IFERROR(SUMIFS(订单明细!$K:$K,订单明细!$I:$I,日订单满足明细!$A$1,订单明细!$C:$C,日订单满足明细!$C$3,订单明细!$A:$A,日订单满足明细!$A8)/SUMIFS(订单明细!$J:$J,订单明细!$I:$I,日订单满足明细!$A$1,订单明细!$C:$C,日订单满足明细!$C$3,订单明细!$A:$A,日订单满足明细!$A8),"") -> 0.97056509 | D8: =IFERROR(SUMIFS(订单明细!$K:$K,订单明细!$I:$I,$A$1,订单明细!$D:$D,日订单满足明细!D$3,订单明细!$A:$A,日订单满足明细!$A8)/SUMIFS(订单明细!$J:$J,订单明细!$I:$I,$A$1,订单明细!$D:$D,日订单满足明细!D$3,订单明细!$A:$A,日订单满足明细!$A8),"") -> 0.9904 | E8: =IFERROR(SUMIFS(订单明细!$K:$K,订单明细!$I:$I,$A$1,订单明细!$D:$D,日订单满足明细!E$3,订单明细!$A:$A,日订单满足明细!$A8)/SUMIFS(订单明细!$J:$J,订单明细!$I:$I,$A$1,订单明细!$D:$D,日订单满足明细!E$3,订单明细!$A:$A,日订单满足明细!$A8),"") -> 0.99638467 | F8: =IFERROR(SUMIFS(订单明细!$K:$K,订单明细!$I:$I,$A$1,订单明细!$D:$D,日订单满足明细!F$3,订单明细!$A:$A,日订单满足明细!$A8)/SUMIFS(订单明细!$J:$J,订单明细!$I:$I,$A$1,订单明细!$D:$D,日订单满足明细!F$3,订单明细!$A:$A,日订单满足明细!$A8),"") -> 1 | G8: =IFERROR(SUMIFS(订单明细!$K:$K,订单明细!$I:$I,$A$1,订单明细!$D:$D,日订单满足明细!G$3,订单明细!$A:$A,日订单满足明细!$A8)/SUMIFS(订单明细!$J:$J,订单明细!$I:$I,$A$1,订单明细!$D:$D,日订单满足明细!G$3,订单明细!$A:$A,日订单满足明细!$A8),"") -> 0.66990291 | H8: =IFERROR(SUMIFS(订单明细!$K:$K,订单明细!$I:$I,$A$1,订单明细!$D:$D,日订单满足明细!H$3,订单明细!$A:$A,日订单满足明细!$A8)/SUMIFS(订单明细!$J:$J,订单明细!$I:$I,$A$1,订单明细!$D:$D,日订单满足明细!H$3,订单明细!$A:$A,日订单满足明细!$A8),"") | I8: =IFERROR(SUMIFS(订单明细!$K:$K,订单明细!$I:$I,$A$1,订单明细!$D:$D,日订单满足明细!I$3,订单明细!$A:$A,日订单满足明细!$A8)/SUMIFS(订单明细!$J:$J,订单明细!$I:$I,$A$1,订单明细!$D:$D,日订单满足明细!I$3,订单明细!$A:$A,日订单满足明细!$A8),"") | J8: =IFERROR(SUMIFS(订单明细!$K:$K,订单明细!$I:$I,$A$1,订单明细!$D:$D,日订单满足明细!J$3,订单明细!$A:$A,日订单满足明细!$A8)/SUMIFS(订单明细!$J:$J,订单明细!$I:$I,$A$1,订单明细!$D:$D,日订单满足明细!J$3,订单明细!$A:$A,日订单满足明细!$A8),"") | K8: =IFERROR(SUMIFS(订单明细!$K:$K,订单明细!$I:$I,$A$1,订单明细!$D:$D,日订单满足明细!K$3,订单明细!$A:$A,日订单满足明细!$A8)/SUMIFS(订单明细!$J:$J,订单明细!$I:$I,$A$1,订单明细!$D:$D,日订单满足明细!K$3,订单明细!$A:$A,日订单满足明细!$A8),"") | M8: 46272 | N8: =IFERROR(SUMIFS(订单明细!$K:$K,订单明细!$I:$I,$M$1,订单明细!$C:$C,日订单满足明细!$N$3,订单明细!$A:$A,日订单满足明细!$A8)/SUMIFS(订单明细!$J:$J,订单明细!$I:$I,$M$1,订单明细!$C:$C,日订单满足明细!$N$3,订单明细!$A:$A,日订单满足明细!$A8),"") -> 1 | O8: =IFERROR(SUMIFS(订单明细!$K:$K,订单明细!$I:$I,$M$1,订单明细!$C:$C,日订单满足明细!$O$3,订单明细!$A:$A,日订单满足明细!$A8)/SUMIFS(订单明细!$J:$J,订单明细!$I:$I,$M$1,订单明细!$C:$C,日订单满足明细!$O$3,订单明细!$A:$A,日订单满足明细!$A8),"") -> 0.98036007 | P8: =IFERROR(SUMIFS(订单明细!$K:$K,订单明细!$I:$I,$M$1,订单明细!$D:$D,日订单满足明细!P$3,订单明细!$A:$A,日订单满足明细!$A8)/SUMIFS(订单明细!$J:$J,订单明细!$I:$I,$M$1,订单明细!$D:$D,日订单满足明细!P$3,订单明细!$A:$A,日订单满足明细!$A8),"") -> 1 | Q8: =IFERROR(SUMIFS(订单明细!$K:$K,订单明细!$I:$I,$M$1,订单明细!$D:$D,日订单满足明细!Q$3,订单明细!$A:$A,日订单满足明细!$A8)/SUMIFS(订单明细!$J:$J,订单明细!$I:$I,$M$1,订单明细!$D:$D,日订单满足明细!Q$3,订单明细!$A:$A,日订单满足明细!$A8),"") -> 0.92727273 | R8: =IFERROR(SUMIFS(订单明细!$K:$K,订单明细!$I:$I,$M$1,订单明细!$D:$D,日订单满足明细!R$3,订单明细!$A:$A,日订单满足明细!$A8)/SUMIFS(订单明细!$J:$J,订单明细!$I:$I,$M$1,订单明细!$D:$D,日订单满足明细!R$3,订单明细!$A:$A,日订单满足明细!$A8),"") -> 1 | S8: =IFERROR(SUMIFS(订单明细!$K:$K,订单明细!$I:$I,$M$1,订单明细!$D:$D,日订单满足明细!S$3,订单明细!$A:$A,日订单满足明细!$A8)/SUMIFS(订单明细!$J:$J,订单明细!$I:$I,$M$1,订单明细!$D:$D,日订单满足明细!S$3,订单明细!$A:$A,日订单满足明细!$A8),"") -> 1 | T8: =IFERROR(SUMIFS(订单明细!$K:$K,订单明细!$I:$I,$M$1,订单明细!$D:$D,日订单满足明细!T$3,订单明细!$A:$A,日订单满足明细!$A8)/SUMIFS(订单明细!$J:$J,订单明细!$I:$I,$M$1,订单明细!$D:$D,日订单满足明细!T$3,订单明细!$A:$A,日订单满足明细!$A8),"") | U8: =IFERROR(SUMIFS(订单明细!$K:$K,订单明细!$I:$I,$M$1,订单明细!$D:$D,日订单满足明细!U$3,订单明细!$A:$A,日订单满足明细!$A8)/SUMIFS(订单明细!$J:$J,订单明细!$I:$I,$M$1,订单明细!$D:$D,日订单满足明细!U$3,订单明细!$A:$A,日订单满足明细!$A8),"") -> 1 | V8: =IFERROR(SUMIFS(订单明细!$K:$K,订单明细!$I:$I,$M$1,订单明细!$D:$D,日订单满足明细!V$3,订单明细!$A:$A,日订单满足明细!$A8)/SUMIFS(订单明细!$J:$J,订单明细!$I:$I,$M$1,订单明细!$D:$D,日订单满足明细!V$3,订单明细!$A:$A,日订单满足明细!$A8),"") | W8: =IFERROR(SUMIFS(订单明细!$K:$K,订单明细!$I:$I,$M$1,订单明细!$D:$D,日订单满足明细!W$3,订单明细!$A:$A,日订单满足明细!$A8)/SUMIFS(订单明细!$J:$J,订单明细!$I:$I,$M$1,订单明细!$D:$D,日订单满足明细!W$3,订单明细!$A:$A,日订单满足明细!$A8),"")
